Workbook

Sheet Synthese
B2: Synthèse des ventes de la pharmacie
B3: Classeur généré par main.py à partir des exports. Dernier jour de données : 08/10/2019.
B5: Début des données | D5: Dernier mois complet | F5: Jours analysés | H5: Groupes suivis
B6: 41641 | D6: 43709 | F6: 2098 | H6: 8
B8: Ce qu'il faut retenir
B9: • Groupe le plus saisonnier : Antihistaminiques (R06), pic en mai (indice 176, 100 = mois moyen) et creux en décembre (indice 51).
B10: • Groupe le plus régulier sur l'année : Anti-inflammatoires (type diclofénac) (M01AB), indices mensuels entre 93 et 107.
B11: • Jour le plus chargé tous groupes confondus : samedi (indice 106) ; le plus calme : dimanche (indice 94).
B12: • Tendance 2014 à 2018 : plus forte hausse pour Asthme et BPCO (+21.2% par an), plus forte baisse pour Antalgiques salicylés (type aspirine) (-8.5% par an).
B13: • Environnement (donnée publique) : à compléter.
B14: • Structure des ventes : tendance + saisonnalité pour 3, tendance seule pour 2, saisonnalité seule pour 2, ni l'une ni l'autre pour 1 groupe(s). Prévision de octobre 2019 : fiable pour 6 groupe(s) sur 8 (erreur moyenne sous 20% sur 24 mois de test) : M01AB, M01AE, N02BA, N02BE, N05B, R06. Un modèle fait mieux qu'une règle naïve pour 5 groupe(s). Détail dans la feuille Prevision.
B16: Les groupes en un coup d'œil
B17: Libellé | C17: Code | D17: Part du volume | E17: Évolution par an (2014 à 2018) | F17: Mois de pic | G17: Mois creux | H17: Jour le plus fort | I17: Variabilité (CV) | J17: Structure détectée | K17: Prévisible ?
B18: Anti-inflammatoires (type diclofénac) | C18: M01AB | D18: 0.083026536 | E18: 0.056114242 | F18: Août | G18: Juin | H18: Samedi | I18: 0.53292447 | J18: Tendance seule | K18: Oui
B19: Anti-inflammatoires (type ibuprofène) | C19: M01AE | D19: 0.064476482 | E19: 0.025176825 | F19: Janv. | G19: Juin | H19: Dimanche | I19: 0.53606274 | J19: Saisonnalité seule | K19: Oui
B20: Antalgiques salicylés (type aspirine) | C20: N02BA | D20: 0.063508276 | E20: -0.085300816 | F20: Févr. | G20: Sept. | H20: Mardi | I20: 0.60170343 | J20: Tendance + saisonnalité | K20: Oui, une règle simple suffit
B21: Antalgiques (type paracétamol) | C21: N02BE | D21: 0.49643862 | E21: 0.053854108 | F21: Janv. | G21: Juil. | H21: Dimanche | I21: 0.52038851 | J21: Saisonnalité seule | K21: Oui
B22: Anxiolytiques | C22: N05B | D22: 0.1440344 | E22: -0.067219566 | F22: Janv. | G22: Mai | H22: Mercredi | I22: 0.62644869 | J22: Tendance seule | K22: Oui
B23: Hypnotiques et sédatifs | C23: N05C | D23: 0.0096556722 | E23: -0.030687979 | F23: Janv. | G23: Avr. | H23: Vendredi | I23: 1.8513001 | J23: Ni l'une ni l'autre | K23: Non
B24: Asthme et BPCO | C24: R03 | D24: 0.091022073 | E24: 0.211559 | F24: Déc. | G24: Juil. | H24: Lundi | I24: 1.1633451 | J24: Tendance + saisonnalité | K24: Non
B25: Antihistaminiques | C25: R06 | D25: 0.047837947 | E25: 0.10450179 | F25: Mai | G25: Déc. | H25: Samedi | I25: 0.82521177 | J25: Tendance + saisonnalité | K25: Oui
B27: Saisonnalité : indice par mois (100 = mois moyen du groupe, à nombre de jours égal)
B28: Groupe | C28: Janv. | D28: Févr. | E28: Mars | F28: Avr. | G28: Mai | H28: Juin | I28: Juil. | J28: Août | K28: Sept. | L28: Oct. | M28: Nov. | N28: Déc.
B29: Anti-inflammatoires (type diclofénac) (M01AB) | C29: 104 | D29: 97 | E29: 97 | F29: 103 | G29: 96 | H29: 93 | I29: 102 | J29: 107 | K29: 98 | L29: 97 | M29: 103 | N29: 103
B30: Anti-inflammatoires (type ibuprofène) (M01AE) | C30: 118 | D30: 118 | E30: 98 | F30: 94 | G30: 94 | H30: 90 | I30: 95 | J30: 92 | K30: 100 | L30: 98 | M30: 96 | N30: 106
B31: Antalgiques salicylés (type aspirine) (N02BA) | C31: 115 | D31: 121 | E31: 102 | F31: 97 | G31: 96 | H31: 96 | I31: 89 | J31: 89 | K31: 86 | L31: 104 | M31: 107 | N31: 98
B32: Antalgiques (type paracétamol) (N02BE) | C32: 143 | D32: 118 | E32: 97 | F32: 87 | G32: 75 | H32: 67 | I32: 63 | J32: 67 | K32: 104 | L32: 138 | M32: 106 | N32: 135
B33: Anxiolytiques (N05B) | C33: 116 | D33: 100 | E33: 93 | F33: 91 | G33: 85 | H33: 89 | I33: 94 | J33: 103 | K33: 104 | L33: 106 | M33: 105 | N33: 113
B34: Hypnotiques et sédatifs (N05C) | C34: 127 | D34: 91 | E34: 105 | F34: 81 | G34: 103 | H34: 99 | I34: 81 | J34: 103 | K34: 88 | L34: 85 | M34: 114 | N34: 123
B35: Asthme et BPCO (R03) | C35: 126 | D35: 120 | E35: 111 | F35: 103 | G35: 89 | H35: 77 | I35: 52 | J35: 55 | K35: 78 | L35: 130 | M35: 110 | N35: 148
B36: Antihistaminiques (R06) | C36: 56 | D36: 58 | E36: 111 | F36: 171 | G36: 176 | H36: 154 | I36: 117 | J36: 94 | K36: 89 | L36: 69 | M36: 55 | N36: 51
B58: Limites : les quantités sont celles du logiciel de caisse, dont l'unité n'est pas documentée, et l'export ne contient aucun prix. Cette analyse porte donc sur des volumes, pas sur un chiffre d'affaires ni une marge. Les volumes de deux groupes différents ne sont pas directement comparables. Écart maximal constaté entre les quatre exports : 2.99 % (détail dans la feuille Etat_donnees).

Sheet Outil
B2: Ventes par groupe et par période
B3: Modifiez uniquement les cases jaunes. Pour un seul jour, mettez la même date en début et en fin.
B5: Date de début | C5: 43709 | D5: =IF($C$5>$C$6,"La date de début est après la date de fin.","")
B6: Date de fin | C6: 43738 | E6: Données disponibles du 02/01/2014 au 08/10/2019.
B7: Jours avec données | C7: =COUNTIFS(Donnees!$A$2:$A$2107,">="&$C$5,Donnees!$A$2:$A$2107,"<="&$C$6) -> 30 | D7: =IF(AND($C$5<=$C$6,$C$7=0),"Aucune donnée sur cette période.","")
B10: Code | C10: Groupe | D10: Afficher | E10: Total sur la période | F10: Moyenne par jour | G10: Maximum sur un jour | H10: Moyenne habituelle par jour | I10: Écart à l'habitude | AA10: Mois | AB10: Ventes des groupes affichés
B11: M01AB | C11: Anti-inflammatoires (type diclofénac) | D11: Oui | E11: =IF($D11="Oui",SUMIFS(Donnees!$B$2:$B$2107,Donnees!$A$2:$A$2107,">="&$C$5,Donnees!$A$2:$A$2107,"<="&$C$6),"") -> 161.07 | F11: =IF(AND($D11="Oui",$C$7>0),E11/$C$7,"") -> 5.369 | G11: =IF(AND($D11="Oui",$C$7>0),_xlfn.MAXIFS(Donnees!$B$2:$B$2107,Donnees!$A$2:$A$2107,">="&$C$5,Donnees!$A$2:$A$2107,"<="&$C$6),"") -> 10.68 | H11: =IF($D11="Oui",AVERAGE(Donnees!$B$2:$B$2107),"") -> 5.0921154 | I11: =IF(AND($D11="Oui",$C$7>0),F11/H11-1,"") -> 0.054375165 | AA11: 41640 | AB11: =IF(AND(EOMONTH($AA11,0)>=$C$5,$AA11<=$C$6),($D$11="Oui")*SUMIFS(Donnees!$B$2:$B$2107,Donnees!$A$2:$A$2107,">="&MAX($AA11,$C$5),Donnees!$A$2:$A$2107,"<="&MIN(EOMONTH($AA11,0),$C$6))+($D$12="Oui")*SUMIFS(Donnees!$C$2:$C$2107,Donnees!$A$2:$A$2107,">="&MAX($AA11,$C$5),Donnees!$A$2:$A$2107,"<="&MIN(EOMONTH($AA11,0),$C$6))+($D$13="Oui")*SUMIFS(Donnees!$D$2:$D$2107,Donnees!$A$2:$A$2107,">="&MAX($AA11,$C$5),Donnees!$A$2:$A$2107,"<="&MIN(EOMONTH($AA11,0),$C$6))+($D$14="Oui")*SUMIFS(Donnees!$E$2:$E$2107,Donnees!$A$2:$A$2107,">="&MAX($AA11,$C$5),Donnees!$A$2:$A$2107,"<="&MIN(EOMONTH($AA11,0),$C$6))+($D$15="Oui")*SUMIFS(Donnees!$F$2:$F$2107,Donnees!$A$2:$A$2107,">="&MAX($AA11,$C$5),Donnees!$A$2:$A$2107,"<="&MIN(EOMONTH($AA11,0),$C$6))+($D$16="Oui")*SUMIFS(Donnees!$G$2:$G$2107,Donnees!$A$2:$A$2107,">="&MAX($AA11,$C$5),Donnees!$A$2:$A$2107,"<="&MIN(EOMONTH($AA11,0),$C$6))+($D$17="Oui")*SUMIFS(Donnees!$H$2:$H$2107,Donnees!$A$2:$A$2107,">="&MAX($AA11,$C$5),Donnees!$A$2:$A$2107,"<="&MIN(EOMONTH($AA11,0),$C$6))+($D$18="Oui")*SUMIFS(Donnees!$I$2:$I$2107,Donnees!$A$2:$A$2107,">="&MAX($AA11,$C$5),Donnees!$A$2:$A$2107,"<="&MIN(EOMONTH($AA11,0),$C$6)),NA()) -> #N/A
B12: M01AE | C12: Anti-inflammatoires (type ibuprofène) | D12: Oui | E12: =IF($D12="Oui",SUMIFS(Donnees!$C$2:$C$2107,Donnees!$A$2:$A$2107,">="&$C$5,Donnees!$A$2:$A$2107,"<="&$C$6),"") -> 111.437 | F12: =IF(AND($D12="Oui",$C$7>0),E12/$C$7,"") -> 3.7145667 | G12: =IF(AND($D12="Oui",$C$7>0),_xlfn.MAXIFS(Donnees!$C$2:$C$2107,Donnees!$A$2:$A$2107,">="&$C$5,Donnees!$A$2:$A$2107,"<="&$C$6),"") -> 9.53 | H12: =IF($D12="Oui",AVERAGE(Donnees!$C$2:$C$2107),"") -> 3.9557688 | I12: =IF(AND($D12="Oui",$C$7>0),F12/H12-1,"") -> -0.06097477 | AA12: 41671 | AB12: =IF(AND(EOMONTH($AA12,0)>=$C$5,$AA12<=$C$6),($D$11="Oui")*SUMIFS(Donnees!$B$2:$B$2107,Donnees!$A$2:$A$2107,">="&MAX($AA12,$C$5),Donnees!$A$2:$A$2107,"<="&MIN(EOMONTH($AA12,0),$C$6))+($D$12="Oui")*SUMIFS(Donnees!$C$2:$C$2107,Donnees!$A$2:$A$2107,">="&MAX($AA12,$C$5),Donnees!$A$2:$A$2107,"<="&MIN(EOMONTH($AA12,0),$C$6))+($D$13="Oui")*SUMIFS(Donnees!$D$2:$D$2107,Donnees!$A$2:$A$2107,">="&MAX($AA12,$C$5),Donnees!$A$2:$A$2107,"<="&MIN(EOMONTH($AA12,0),$C$6))+($D$14="Oui")*SUMIFS(Donnees!$E$2:$E$2107,Donnees!$A$2:$A$2107,">="&MAX($AA12,$C$5),Donnees!$A$2:$A$2107,"<="&MIN(EOMONTH($AA12,0),$C$6))+($D$15="Oui")*SUMIFS(Donnees!$F$2:$F$2107,Donnees!$A$2:$A$2107,">="&MAX($AA12,$C$5),Donnees!$A$2:$A$2107,"<="&MIN(EOMONTH($AA12,0),$C$6))+($D$16="Oui")*SUMIFS(Donnees!$G$2:$G$2107,Donnees!$A$2:$A$2107,">="&MAX($AA12,$C$5),Donnees!$A$2:$A$2107,"<="&MIN(EOMONTH($AA12,0),$C$6))+($D$17="Oui")*SUMIFS(Donnees!$H$2:$H$2107,Donnees!$A$2:$A$2107,">="&MAX($AA12,$C$5),Donnees!$A$2:$A$2107,"<="&MIN(EOMONTH($AA12,0),$C$6))+($D$18="Oui")*SUMIFS(Donnees!$I$2:$I$2107,Donnees!$A$2:$A$2107,">="&MAX($AA12,$C$5),Donnees!$A$2:$A$2107,"<="&MIN(EOMONTH($AA12,0),$C$6)),NA()) -> #N/A
B13: N02BA | C13: Antalgiques salicylés (type aspirine) | D13: Oui | E13: =IF($D13="Oui",SUMIFS(Donnees!$D$2:$D$2107,Donnees!$A$2:$A$2107,">="&$C$5,Donnees!$A$2:$A$2107,"<="&$C$6),"") -> 93.5 | F13: =IF(AND($D13="Oui",$C$7>0),E13/$C$7,"") -> 3.1166667 | G13: =IF(AND($D13="Oui",$C$7>0),_xlfn.MAXIFS(Donnees!$D$2:$D$2107,Donnees!$A$2:$A$2107,">="&$C$5,Donnees!$A$2:$A$2107,"<="&$C$6),"") -> 7 | H13: =IF($D13="Oui",AVERAGE(Donnees!$D$2:$D$2107),"") -> 3.8887273 | I13: =IF(AND($D13="Oui",$C$7>0),F13/H13-1,"") -> -0.19853812 | AA13: 41699 | AB13: =IF(AND(EOMONTH($AA13,0)>=$C$5,$AA13<=$C$6),($D$11="Oui")*SUMIFS(Donnees!$B$2:$B$2107,Donnees!$A$2:$A$2107,">="&MAX($AA13,$C$5),Donnees!$A$2:$A$2107,"<="&MIN(EOMONTH($AA13,0),$C$6))+($D$12="Oui")*SUMIFS(Donnees!$C$2:$C$2107,Donnees!$A$2:$A$2107,">="&MAX($AA13,$C$5),Donnees!$A$2:$A$2107,"<="&MIN(EOMONTH($AA13,0),$C$6))+($D$13="Oui")*SUMIFS(Donnees!$D$2:$D$2107,Donnees!$A$2:$A$2107,">="&MAX($AA13,$C$5),Donnees!$A$2:$A$2107,"<="&MIN(EOMONTH($AA13,0),$C$6))+($D$14="Oui")*SUMIFS(Donnees!$E$2:$E$2107,Donnees!$A$2:$A$2107,">="&MAX($AA13,$C$5),Donnees!$A$2:$A$2107,"<="&MIN(EOMONTH($AA13,0),$C$6))+($D$15="Oui")*SUMIFS(Donnees!$F$2:$F$2107,Donnees!$A$2:$A$2107,">="&MAX($AA13,$C$5),Donnees!$A$2:$A$2107,"<="&MIN(EOMONTH($AA13,0),$C$6))+($D$16="Oui")*SUMIFS(Donnees!$G$2:$G$2107,Donnees!$A$2:$A$2107,">="&MAX($AA13,$C$5),Donnees!$A$2:$A$2107,"<="&MIN(EOMONTH($AA13,0),$C$6))+($D$17="Oui")*SUMIFS(Donnees!$H$2:$H$2107,Donnees!$A$2:$A$2107,">="&MAX($AA13,$C$5),Donnees!$A$2:$A$2107,"<="&MIN(EOMONTH($AA13,0),$C$6))+($D$18="Oui")*SUMIFS(Donnees!$I$2:$I$2107,Donnees!$A$2:$A$2107,">="&MAX($AA13,$C$5),Donnees!$A$2:$A$2107,"<="&MIN(EOMONTH($AA13,0),$C$6)),NA()) -> #N/A
B14: N02BE | C14: Antalgiques (type paracétamol) | D14: Oui | E14: =IF($D14="Oui",SUMIFS(Donnees!$E$2:$E$2107,Donnees!$A$2:$A$2107,">="&$C$5,Donnees!$A$2:$A$2107,"<="&$C$6),"") -> 984.48 | F14: =IF(AND($D14="Oui",$C$7>0),E14/$C$7,"") -> 32.816 | G14: =IF(AND($D14="Oui",$C$7>0),_xlfn.MAXIFS(Donnees!$E$2:$E$2107,Donnees!$A$2:$A$2107,">="&$C$5,Donnees!$A$2:$A$2107,"<="&$C$6),"") -> 67.8 | H14: =IF($D14="Oui",AVERAGE(Donnees!$E$2:$E$2107),"") -> 30.46134 | I14: =IF(AND($D14="Oui",$C$7>0),F14/H14-1,"") -> 0.077299966 | AA14: 41730 | AB14: =IF(AND(EOMONTH($AA14,0)>=$C$5,$AA14<=$C$6),($D$11="Oui")*SUMIFS(Donnees!$B$2:$B$2107,Donnees!$A$2:$A$2107,">="&MAX($AA14,$C$5),Donnees!$A$2:$A$2107,"<="&MIN(EOMONTH($AA14,0),$C$6))+($D$12="Oui")*SUMIFS(Donnees!$C$2:$C$2107,Donnees!$A$2:$A$2107,">="&MAX($AA14,$C$5),Donnees!$A$2:$A$2107,"<="&MIN(EOMONTH($AA14,0),$C$6))+($D$13="Oui")*SUMIFS(Donnees!$D$2:$D$2107,Donnees!$A$2:$A$2107,">="&MAX($AA14,$C$5),Donnees!$A$2:$A$2107,"<="&MIN(EOMONTH($AA14,0),$C$6))+($D$14="Oui")*SUMIFS(Donnees!$E$2:$E$2107,Donnees!$A$2:$A$2107,">="&MAX($AA14,$C$5),Donnees!$A$2:$A$2107,"<="&MIN(EOMONTH($AA14,0),$C$6))+($D$15="Oui")*SUMIFS(Donnees!$F$2:$F$2107,Donnees!$A$2:$A$2107,">="&MAX($AA14,$C$5),Donnees!$A$2:$A$2107,"<="&MIN(EOMONTH($AA14,0),$C$6))+($D$16="Oui")*SUMIFS(Donnees!$G$2:$G$2107,Donnees!$A$2:$A$2107,">="&MAX($AA14,$C$5),Donnees!$A$2:$A$2107,"<="&MIN(EOMONTH($AA14,0),$C$6))+($D$17="Oui")*SUMIFS(Donnees!$H$2:$H$2107,Donnees!$A$2:$A$2107,">="&MAX($AA14,$C$5),Donnees!$A$2:$A$2107,"<="&MIN(EOMONTH($AA14,0),$C$6))+($D$18="Oui")*SUMIFS(Donnees!$I$2:$I$2107,Donnees!$A$2:$A$2107,">="&MAX($AA14,$C$5),Donnees!$A$2:$A$2107,"<="&MIN(EOMONTH($AA14,0),$C$6)),NA()) -> #N/A
B15: N05B | C15: Anxiolytiques | D15: Oui | E15: =IF($D15="Oui",SUMIFS(Donnees!$F$2:$F$2107,Donnees!$A$2:$A$2107,">="&$C$5,Donnees!$A$2:$A$2107,"<="&$C$6),"") -> 227.8 | F15: =IF(AND($D15="Oui",$C$7>0),E15/$C$7,"") -> 7.5933333 | G15: =IF(AND($D15="Oui",$C$7>0),_xlfn.MAXIFS(Donnees!$F$2:$F$2107,Donnees!$A$2:$A$2107,">="&$C$5,Donnees!$A$2:$A$2107,"<="&$C$6),"") -> 17 | H15: =IF($D15="Oui",AVERAGE(Donnees!$F$2:$F$2107),"") -> 8.8380856 | I15: =IF(AND($D15="Oui",$C$7>0),F15/H15-1,"") -> -0.14083958 | AA15: 41760 | AB15: =IF(AND(EOMONTH($AA15,0)>=$C$5,$AA15<=$C$6),($D$11="Oui")*SUMIFS(Donnees!$B$2:$B$2107,Donnees!$A$2:$A$2107,">="&MAX($AA15,$C$5),Donnees!$A$2:$A$2107,"<="&MIN(EOMONTH($AA15,0),$C$6))+($D$12="Oui")*SUMIFS(Donnees!$C$2:$C$2107,Donnees!$A$2:$A$2107,">="&MAX($AA15,$C$5),Donnees!$A$2:$A$2107,"<="&MIN(EOMONTH($AA15,0),$C$6))+($D$13="Oui")*SUMIFS(Donnees!$D$2:$D$2107,Donnees!$A$2:$A$2107,">="&MAX($AA15,$C$5),Donnees!$A$2:$A$2107,"<="&MIN(EOMONTH($AA15,0),$C$6))+($D$14="Oui")*SUMIFS(Donnees!$E$2:$E$2107,Donnees!$A$2:$A$2107,">="&MAX($AA15,$C$5),Donnees!$A$2:$A$2107,"<="&MIN(EOMONTH($AA15,0),$C$6))+($D$15="Oui")*SUMIFS(Donnees!$F$2:$F$2107,Donnees!$A$2:$A$2107,">="&MAX($AA15,$C$5),Donnees!$A$2:$A$2107,"<="&MIN(EOMONTH($AA15,0),$C$6))+($D$16="Oui")*SUMIFS(Donnees!$G$2:$G$2107,Donnees!$A$2:$A$2107,">="&MAX($AA15,$C$5),Donnees!$A$2:$A$2107,"<="&MIN(EOMONTH($AA15,0),$C$6))+($D$17="Oui")*SUMIFS(Donnees!$H$2:$H$2107,Donnees!$A$2:$A$2107,">="&MAX($AA15,$C$5),Donnees!$A$2:$A$2107,"<="&MIN(EOMONTH($AA15,0),$C$6))+($D$18="Oui")*SUMIFS(Donnees!$I$2:$I$2107,Donnees!$A$2:$A$2107,">="&MAX($AA15,$C$5),Donnees!$A$2:$A$2107,"<="&MIN(EOMONTH($AA15,0),$C$6)),NA()) -> #N/A
B16: N05C | C16: Hypnotiques et sédatifs | D16: Oui | E16: =IF($D16="Oui",SUMIFS(Donnees!$G$2:$G$2107,Donnees!$A$2:$A$2107,">="&$C$5,Donnees!$A$2:$A$2107,"<="&$C$6),"") -> 16 | F16: =IF(AND($D16="Oui",$C$7>0),E16/$C$7,"") -> 0.53333333 | G16: =IF(AND($D16="Oui",$C$7>0),_xlfn.MAXIFS(Donnees!$G$2:$G$2107,Donnees!$A$2:$A$2107,">="&$C$5,Donnees!$A$2:$A$2107,"<="&$C$6),"") -> 3 | H16: =IF($D16="Oui",AVERAGE(Donnees!$G$2:$G$2107),"") -> 0.59306743 | I16: =IF(AND($D16="Oui",$C$7>0),F16/H16-1,"") -> -0.10072058 | AA16: 41791 | AB16: =IF(AND(EOMONTH($AA16,0)>=$C$5,$AA16<=$C$6),($D$11="Oui")*SUMIFS(Donnees!$B$2:$B$2107,Donnees!$A$2:$A$2107,">="&MAX($AA16,$C$5),Donnees!$A$2:$A$2107,"<="&MIN(EOMONTH($AA16,0),$C$6))+($D$12="Oui")*SUMIFS(Donnees!$C$2:$C$2107,Donnees!$A$2:$A$2107,">="&MAX($AA16,$C$5),Donnees!$A$2:$A$2107,"<="&MIN(EOMONTH($AA16,0),$C$6))+($D$13="Oui")*SUMIFS(Donnees!$D$2:$D$2107,Donnees!$A$2:$A$2107,">="&MAX($AA16,$C$5),Donnees!$A$2:$A$2107,"<="&MIN(EOMONTH($AA16,0),$C$6))+($D$14="Oui")*SUMIFS(Donnees!$E$2:$E$2107,Donnees!$A$2:$A$2107,">="&MAX($AA16,$C$5),Donnees!$A$2:$A$2107,"<="&MIN(EOMONTH($AA16,0),$C$6))+($D$15="Oui")*SUMIFS(Donnees!$F$2:$F$2107,Donnees!$A$2:$A$2107,">="&MAX($AA16,$C$5),Donnees!$A$2:$A$2107,"<="&MIN(EOMONTH($AA16,0),$C$6))+($D$16="Oui")*SUMIFS(Donnees!$G$2:$G$2107,Donnees!$A$2:$A$2107,">="&MAX($AA16,$C$5),Donnees!$A$2:$A$2107,"<="&MIN(EOMONTH($AA16,0),$C$6))+($D$17="Oui")*SUMIFS(Donnees!$H$2:$H$2107,Donnees!$A$2:$A$2107,">="&MAX($AA16,$C$5),Donnees!$A$2:$A$2107,"<="&MIN(EOMONTH($AA16,0),$C$6))+($D$18="Oui")*SUMIFS(Donnees!$I$2:$I$2107,Donnees!$A$2:$A$2107,">="&MAX($AA16,$C$5),Donnees!$A$2:$A$2107,"<="&MIN(EOMONTH($AA16,0),$C$6)),NA()) -> #N/A
B17: R03 | C17: Asthme et BPCO | D17: Oui | E17: =IF($D17="Oui",SUMIFS(Donnees!$H$2:$H$2107,Donnees!$A$2:$A$2107,">="&$C$5,Donnees!$A$2:$A$2107,"<="&$C$6),"") -> 121.41667 | F17: =IF(AND($D17="Oui",$C$7>0),E17/$C$7,"") -> 4.0472222 | G17: =IF(AND($D17="Oui",$C$7>0),_xlfn.MAXIFS(Donnees!$H$2:$H$2107,Donnees!$A$2:$A$2107,">="&$C$5,Donnees!$A$2:$A$2107,"<="&$C$6),"") -> 31 | H17: =IF($D17="Oui",AVERAGE(Donnees!$H$2:$H$2107),"") -> 5.5769626 | I17: =IF(AND($D17="Oui",$C$7>0),F17/H17-1,"") -> -0.27429634 | AA17: 41821 | AB17: =IF(AND(EOMONTH($AA17,0)>=$C$5,$AA17<=$C$6),($D$11="Oui")*SUMIFS(Donnees!$B$2:$B$2107,Donnees!$A$2:$A$2107,">="&MAX($AA17,$C$5),Donnees!$A$2:$A$2107,"<="&MIN(EOMONTH($AA17,0),$C$6))+($D$12="Oui")*SUMIFS(Donnees!$C$2:$C$2107,Donnees!$A$2:$A$2107,">="&MAX($AA17,$C$5),Donnees!$A$2:$A$2107,"<="&MIN(EOMONTH($AA17,0),$C$6))+($D$13="Oui")*SUMIFS(Donnees!$D$2:$D$2107,Donnees!$A$2:$A$2107,">="&MAX($AA17,$C$5),Donnees!$A$2:$A$2107,"<="&MIN(EOMONTH($AA17,0),$C$6))+($D$14="Oui")*SUMIFS(Donnees!$E$2:$E$2107,Donnees!$A$2:$A$2107,">="&MAX($AA17,$C$5),Donnees!$A$2:$A$2107,"<="&MIN(EOMONTH($AA17,0),$C$6))+($D$15="Oui")*SUMIFS(Donnees!$F$2:$F$2107,Donnees!$A$2:$A$2107,">="&MAX($AA17,$C$5),Donnees!$A$2:$A$2107,"<="&MIN(EOMONTH($AA17,0),$C$6))+($D$16="Oui")*SUMIFS(Donnees!$G$2:$G$2107,Donnees!$A$2:$A$2107,">="&MAX($AA17,$C$5),Donnees!$A$2:$A$2107,"<="&MIN(EOMONTH($AA17,0),$C$6))+($D$17="Oui")*SUMIFS(Donnees!$H$2:$H$2107,Donnees!$A$2:$A$2107,">="&MAX($AA17,$C$5),Donnees!$A$2:$A$2107,"<="&MIN(EOMONTH($AA17,0),$C$6))+($D$18="Oui")*SUMIFS(Donnees!$I$2:$I$2107,Donnees!$A$2:$A$2107,">="&MAX($AA17,$C$5),Donnees!$A$2:$A$2107,"<="&MIN(EOMONTH($AA17,0),$C$6)),NA()) -> #N/A
B18: R06 | C18: Antihistaminiques | D18: Oui | E18: =IF($D18="Oui",SUMIFS(Donnees!$I$2:$I$2107,Donnees!$A$2:$A$2107,">="&$C$5,Donnees!$A$2:$A$2107,"<="&$C$6),"") -> 109.1 | F18: =IF(AND($D18="Oui",$C$7>0),E18/$C$7,"") -> 3.6366667 | G18: =IF(AND($D18="Oui",$C$7>0),_xlfn.MAXIFS(Donnees!$I$2:$I$2107,Donnees!$A$2:$A$2107,">="&$C$5,Donnees!$A$2:$A$2107,"<="&$C$6),"") -> 10 | H18: =IF($D18="Oui",AVERAGE(Donnees!$I$2:$I$2107),"") -> 2.9271035 | I18: =IF(AND($D18="Oui",$C$7>0),F18/H18-1,"") -> 0.24241136 | AA18: 41852 | AB18: =IF(AND(EOMONTH($AA18,0)>=$C$5,$AA18<=$C$6),($D$11="Oui")*SUMIFS(Donnees!$B$2:$B$2107,Donnees!$A$2:$A$2107,">="&MAX($AA18,$C$5),Donnees!$A$2:$A$2107,"<="&MIN(EOMONTH($AA18,0),$C$6))+($D$12="Oui")*SUMIFS(Donnees!$C$2:$C$2107,Donnees!$A$2:$A$2107,">="&MAX($AA18,$C$5),Donnees!$A$2:$A$2107,"<="&MIN(EOMONTH($AA18,0),$C$6))+($D$13="Oui")*SUMIFS(Donnees!$D$2:$D$2107,Donnees!$A$2:$A$2107,">="&MAX($AA18,$C$5),Donnees!$A$2:$A$2107,"<="&MIN(EOMONTH($AA18,0),$C$6))+($D$14="Oui")*SUMIFS(Donnees!$E$2:$E$2107,Donnees!$A$2:$A$2107,">="&MAX($AA18,$C$5),Donnees!$A$2:$A$2107,"<="&MIN(EOMONTH($AA18,0),$C$6))+($D$15="Oui")*SUMIFS(Donnees!$F$2:$F$2107,Donnees!$A$2:$A$2107,">="&MAX($AA18,$C$5),Donnees!$A$2:$A$2107,"<="&MIN(EOMONTH($AA18,0),$C$6))+($D$16="Oui")*SUMIFS(Donnees!$G$2:$G$2107,Donnees!$A$2:$A$2107,">="&MAX($AA18,$C$5),Donnees!$A$2:$A$2107,"<="&MIN(EOMONTH($AA18,0),$C$6))+($D$17="Oui")*SUMIFS(Donnees!$H$2:$H$2107,Donnees!$A$2:$A$2107,">="&MAX($AA18,$C$5),Donnees!$A$2:$A$2107,"<="&MIN(EOMONTH($AA18,0),$C$6))+($D$18="Oui")*SUMIFS(Donnees!$I$2:$I$2107,Donnees!$A$2:$A$2107,">="&MAX($AA18,$C$5),Donnees!$A$2:$A$2107,"<="&MIN(EOMONTH($AA18,0),$C$6)),NA()) -> #N/A
C19: Total des groupes affichés | E19: =SUM(E11:E18) -> 1824.8037 | F19: =IF($C$7>0,E19/$C$7,"") -> 60.826789 | AA19: 41883 | AB19: =IF(AND(EOMONTH($AA19,0)>=$C$5,$AA19<=$C$6),($D$11="Oui")*SUMIFS(Donnees!$B$2:$B$2107,Donnees!$A$2:$A$2107,">="&MAX($AA19,$C$5),Donnees!$A$2:$A$2107,"<="&MIN(EOMONTH($AA19,0),$C$6))+($D$12="Oui")*SUMIFS(Donnees!$C$2:$C$2107,Donnees!$A$2:$A$2107,">="&MAX($AA19,$C$5),Donnees!$A$2:$A$2107,"<="&MIN(EOMONTH($AA19,0),$C$6))+($D$13="Oui")*SUMIFS(Donnees!$D$2:$D$2107,Donnees!$A$2:$A$2107,">="&MAX($AA19,$C$5),Donnees!$A$2:$A$2107,"<="&MIN(EOMONTH($AA19,0),$C$6))+($D$14="Oui")*SUMIFS(Donnees!$E$2:$E$2107,Donnees!$A$2:$A$2107,">="&MAX($AA19,$C$5),Donnees!$A$2:$A$2107,"<="&MIN(EOMONTH($AA19,0),$C$6))+($D$15="Oui")*SUMIFS(Donnees!$F$2:$F$2107,Donnees!$A$2:$A$2107,">="&MAX($AA19,$C$5),Donnees!$A$2:$A$2107,"<="&MIN(EOMONTH($AA19,0),$C$6))+($D$16="Oui")*SUMIFS(Donnees!$G$2:$G$2107,Donnees!$A$2:$A$2107,">="&MAX($AA19,$C$5),Donnees!$A$2:$A$2107,"<="&MIN(EOMONTH($AA19,0),$C$6))+($D$17="Oui")*SUMIFS(Donnees!$H$2:$H$2107,Donnees!$A$2:$A$2107,">="&MAX($AA19,$C$5),Donnees!$A$2:$A$2107,"<="&MIN(EOMONTH($AA19,0),$C$6))+($D$18="Oui")*SUMIFS(Donnees!$I$2:$I$2107,Donnees!$A$2:$A$2107,">="&MAX($AA19,$C$5),Donnees!$A$2:$A$2107,"<="&MIN(EOMONTH($AA19,0),$C$6)),NA()) -> #N/A
AA20: 41913 | AB20: =IF(AND(EOMONTH($AA20,0)>=$C$5,$AA20<=$C$6),($D$11="Oui")*SUMIFS(Donnees!$B$2:$B$2107,Donnees!$A$2:$A$2107,">="&MAX($AA20,$C$5),Donnees!$A$2:$A$2107,"<="&MIN(EOMONTH($AA20,0),$C$6))+($D$12="Oui")*SUMIFS(Donnees!$C$2:$C$2107,Donnees!$A$2:$A$2107,">="&MAX($AA20,$C$5),Donnees!$A$2:$A$2107,"<="&MIN(EOMONTH($AA20,0),$C$6))+($D$13="Oui")*SUMIFS(Donnees!$D$2:$D$2107,Donnees!$A$2:$A$2107,">="&MAX($AA20,$C$5),Donnees!$A$2:$A$2107,"<="&MIN(EOMONTH($AA20,0),$C$6))+($D$14="Oui")*SUMIFS(Donnees!$E$2:$E$2107,Donnees!$A$2:$A$2107,">="&MAX($AA20,$C$5),Donnees!$A$2:$A$2107,"<="&MIN(EOMONTH($AA20,0),$C$6))+($D$15="Oui")*SUMIFS(Donnees!$F$2:$F$2107,Donnees!$A$2:$A$2107,">="&MAX($AA20,$C$5),Donnees!$A$2:$A$2107,"<="&MIN(EOMONTH($AA20,0),$C$6))+($D$16="Oui")*SUMIFS(Donnees!$G$2:$G$2107,Donnees!$A$2:$A$2107,">="&MAX($AA20,$C$5),Donnees!$A$2:$A$2107,"<="&MIN(EOMONTH($AA20,0),$C$6))+($D$17="Oui")*SUMIFS(Donnees!$H$2:$H$2107,Donnees!$A$2:$A$2107,">="&MAX($AA20,$C$5),Donnees!$A$2:$A$2107,"<="&MIN(EOMONTH($AA20,0),$C$6))+($D$18="Oui")*SUMIFS(Donnees!$I$2:$I$2107,Donnees!$A$2:$A$2107,">="&MAX($AA20,$C$5),Donnees!$A$2:$A$2107,"<="&MIN(EOMONTH($AA20,0),$C$6)),NA()) -> #N/A
AA21: 41944 | AB21: =IF(AND(EOMONTH($AA21,0)>=$C$5,$AA21<=$C$6),($D$11="Oui")*SUMIFS(Donnees!$B$2:$B$2107,Donnees!$A$2:$A$2107,">="&MAX($AA21,$C$5),Donnees!$A$2:$A$2107,"<="&MIN(EOMONTH($AA21,0),$C$6))+($D$12="Oui")*SUMIFS(Donnees!$C$2:$C$2107,Donnees!$A$2:$A$2107,">="&MAX($AA21,$C$5),Donnees!$A$2:$A$2107,"<="&MIN(EOMONTH($AA21,0),$C$6))+($D$13="Oui")*SUMIFS(Donnees!$D$2:$D$2107,Donnees!$A$2:$A$2107,">="&MAX($AA21,$C$5),Donnees!$A$2:$A$2107,"<="&MIN(EOMONTH($AA21,0),$C$6))+($D$14="Oui")*SUMIFS(Donnees!$E$2:$E$2107,Donnees!$A$2:$A$2107,">="&MAX($AA21,$C$5),Donnees!$A$2:$A$2107,"<="&MIN(EOMONTH($AA21,0),$C$6))+($D$15="Oui")*SUMIFS(Donnees!$F$2:$F$2107,Donnees!$A$2:$A$2107,">="&MAX($AA21,$C$5),Donnees!$A$2:$A$2107,"<="&MIN(EOMONTH($AA21,0),$C$6))+($D$16="Oui")*SUMIFS(Donnees!$G$2:$G$2107,Donnees!$A$2:$A$2107,">="&MAX($AA21,$C$5),Donnees!$A$2:$A$2107,"<="&MIN(EOMONTH($AA21,0),$C$6))+($D$17="Oui")*SUMIFS(Donnees!$H$2:$H$2107,Donnees!$A$2:$A$2107,">="&MAX($AA21,$C$5),Donnees!$A$2:$A$2107,"<="&MIN(EOMONTH($AA21,0),$C$6))+($D$18="Oui")*SUMIFS(Donnees!$I$2:$I$2107,Donnees!$A$2:$A$2107,">="&MAX($AA21,$C$5),Donnees!$A$2:$A$2107,"<="&MIN(EOMONTH($AA21,0),$C$6)),NA()) -> #N/A
AA22: 41974 | AB22: =IF(AND(EOMONTH($AA22,0)>=$C$5,$AA22<=$C$6),($D$11="Oui")*SUMIFS(Donnees!$B$2:$B$2107,Donnees!$A$2:$A$2107,">="&MAX($AA22,$C$5),Donnees!$A$2:$A$2107,"<="&MIN(EOMONTH($AA22,0),$C$6))+($D$12="Oui")*SUMIFS(Donnees!$C$2:$C$2107,Donnees!$A$2:$A$2107,">="&MAX($AA22,$C$5),Donnees!$A$2:$A$2107,"<="&MIN(EOMONTH($AA22,0),$C$6))+($D$13="Oui")*SUMIFS(Donnees!$D$2:$D$2107,Donnees!$A$2:$A$2107,">="&MAX($AA22,$C$5),Donnees!$A$2:$A$2107,"<="&MIN(EOMONTH($AA22,0),$C$6))+($D$14="Oui")*SUMIFS(Donnees!$E$2:$E$2107,Donnees!$A$2:$A$2107,">="&MAX($AA22,$C$5),Donnees!$A$2:$A$2107,"<="&MIN(EOMONTH($AA22,0),$C$6))+($D$15="Oui")*SUMIFS(Donnees!$F$2:$F$2107,Donnees!$A$2:$A$2107,">="&MAX($AA22,$C$5),Donnees!$A$2:$A$2107,"<="&MIN(EOMONTH($AA22,0),$C$6))+($D$16="Oui")*SUMIFS(Donnees!$G$2:$G$2107,Donnees!$A$2:$A$2107,">="&MAX($AA22,$C$5),Donnees!$A$2:$A$2107,"<="&MIN(EOMONTH($AA22,0),$C$6))+($D$17="Oui")*SUMIFS(Donnees!$H$2:$H$2107,Donnees!$A$2:$A$2107,">="&MAX($AA22,$C$5),Donnees!$A$2:$A$2107,"<="&MIN(EOMONTH($AA22,0),$C$6))+($D$18="Oui")*SUMIFS(Donnees!$I$2:$I$2107,Donnees!$A$2:$A$2107,">="&MAX($AA22,$C$5),Donnees!$A$2:$A$2107,"<="&MIN(EOMONTH($AA22,0),$C$6)),NA()) -> #N/A
AA23: 42005 | AB23: =IF(AND(EOMONTH($AA23,0)>=$C$5,$AA23<=$C$6),($D$11="Oui")*SUMIFS(Donnees!$B$2:$B$2107,Donnees!$A$2:$A$2107,">="&MAX($AA23,$C$5),Donnees!$A$2:$A$2107,"<="&MIN(EOMONTH($AA23,0),$C$6))+($D$12="Oui")*SUMIFS(Donnees!$C$2:$C$2107,Donnees!$A$2:$A$2107,">="&MAX($AA23,$C$5),Donnees!$A$2:$A$2107,"<="&MIN(EOMONTH($AA23,0),$C$6))+($D$13="Oui")*SUMIFS(Donnees!$D$2:$D$2107,Donnees!$A$2:$A$2107,">="&MAX($AA23,$C$5),Donnees!$A$2:$A$2107,"<="&MIN(EOMONTH($AA23,0),$C$6))+($D$14="Oui")*SUMIFS(Donnees!$E$2:$E$2107,Donnees!$A$2:$A$2107,">="&MAX($AA23,$C$5),Donnees!$A$2:$A$2107,"<="&MIN(EOMONTH($AA23,0),$C$6))+($D$15="Oui")*SUMIFS(Donnees!$F$2:$F$2107,Donnees!$A$2:$A$2107,">="&MAX($AA23,$C$5),Donnees!$A$2:$A$2107,"<="&MIN(EOMONTH($AA23,0),$C$6))+($D$16="Oui")*SUMIFS(Donnees!$G$2:$G$2107,Donnees!$A$2:$A$2107,">="&MAX($AA23,$C$5),Donnees!$A$2:$A$2107,"<="&MIN(EOMONTH($AA23,0),$C$6))+($D$17="Oui")*SUMIFS(Donnees!$H$2:$H$2107,Donnees!$A$2:$A$2107,">="&MAX($AA23,$C$5),Donnees!$A$2:$A$2107,"<="&MIN(EOMONTH($AA23,0),$C$6))+($D$18="Oui")*SUMIFS(Donnees!$I$2:$I$2107,Donnees!$A$2:$A$2107,">="&MAX($AA23,$C$5),Donnees!$A$2:$A$2107,"<="&MIN(EOMONTH($AA23,0),$C$6)),NA()) -> #N/A
AA24: 42036 | AB24: =IF(AND(EOMONTH($AA24,0)>=$C$5,$AA24<=$C$6),($D$11="Oui")*SUMIFS(Donnees!$B$2:$B$2107,Donnees!$A$2:$A$2107,">="&MAX($AA24,$C$5),Donnees!$A$2:$A$2107,"<="&MIN(EOMONTH($AA24,0),$C$6))+($D$12="Oui")*SUMIFS(Donnees!$C$2:$C$2107,Donnees!$A$2:$A$2107,">="&MAX($AA24,$C$5),Donnees!$A$2:$A$2107,"<="&MIN(EOMONTH($AA24,0),$C$6))+($D$13="Oui")*SUMIFS(Donnees!$D$2:$D$2107,Donnees!$A$2:$A$2107,">="&MAX($AA24,$C$5),Donnees!$A$2:$A$2107,"<="&MIN(EOMONTH($AA24,0),$C$6))+($D$14="Oui")*SUMIFS(Donnees!$E$2:$E$2107,Donnees!$A$2:$A$2107,">="&MAX($AA24,$C$5),Donnees!$A$2:$A$2107,"<="&MIN(EOMONTH($AA24,0),$C$6))+($D$15="Oui")*SUMIFS(Donnees!$F$2:$F$2107,Donnees!$A$2:$A$2107,">="&MAX($AA24,$C$5),Donnees!$A$2:$A$2107,"<="&MIN(EOMONTH($AA24,0),$C$6))+($D$16="Oui")*SUMIFS(Donnees!$G$2:$G$2107,Donnees!$A$2:$A$2107,">="&MAX($AA24,$C$5),Donnees!$A$2:$A$2107,"<="&MIN(EOMONTH($AA24,0),$C$6))+($D$17="Oui")*SUMIFS(Donnees!$H$2:$H$2107,Donnees!$A$2:$A$2107,">="&MAX($AA24,$C$5),Donnees!$A$2:$A$2107,"<="&MIN(EOMONTH($AA24,0),$C$6))+($D$18="Oui")*SUMIFS(Donnees!$I$2:$I$2107,Donnees!$A$2:$A$2107,">="&MAX($AA24,$C$5),Donnees!$A$2:$A$2107,"<="&MIN(EOMONTH($AA24,0),$C$6)),NA()) -> #N/A
AA25: 42064 | AB25: =IF(AND(EOMONTH($AA25,0)>=$C$5,$AA25<=$C$6),($D$11="Oui")*SUMIFS(Donnees!$B$2:$B$2107,Donnees!$A$2:$A$2107,">="&MAX($AA25,$C$5),Donnees!$A$2:$A$2107,"<="&MIN(EOMONTH($AA25,0),$C$6))+($D$12="Oui")*SUMIFS(Donnees!$C$2:$C$2107,Donnees!$A$2:$A$2107,">="&MAX($AA25,$C$5),Donnees!$A$2:$A$2107,"<="&MIN(EOMONTH($AA25,0),$C$6))+($D$13="Oui")*SUMIFS(Donnees!$D$2:$D$2107,Donnees!$A$2:$A$2107,">="&MAX($AA25,$C$5),Donnees!$A$2:$A$2107,"<="&MIN(EOMONTH($AA25,0),$C$6))+($D$14="Oui")*SUMIFS(Donnees!$E$2:$E$2107,Donnees!$A$2:$A$2107,">="&MAX($AA25,$C$5),Donnees!$A$2:$A$2107,"<="&MIN(EOMONTH($AA25,0),$C$6))+($D$15="Oui")*SUMIFS(Donnees!$F$2:$F$2107,Donnees!$A$2:$A$2107,">="&MAX($AA25,$C$5),Donnees!$A$2:$A$2107,"<="&MIN(EOMONTH($AA25,0),$C$6))+($D$16="Oui")*SUMIFS(Donnees!$G$2:$G$2107,Donnees!$A$2:$A$2107,">="&MAX($AA25,$C$5),Donnees!$A$2:$A$2107,"<="&MIN(EOMONTH($AA25,0),$C$6))+($D$17="Oui")*SUMIFS(Donnees!$H$2:$H$2107,Donnees!$A$2:$A$2107,">="&MAX($AA25,$C$5),Donnees!$A$2:$A$2107,"<="&MIN(EOMONTH($AA25,0),$C$6))+($D$18="Oui")*SUMIFS(Donnees!$I$2:$I$2107,Donnees!$A$2:$A$2107,">="&MAX($AA25,$C$5),Donnees!$A$2:$A$2107,"<="&MIN(EOMONTH($AA25,0),$C$6)),NA()) -> #N/A
AA26: 42095 | AB26: =IF(AND(EOMONTH($AA26,0)>=$C$5,$AA26<=$C$6),($D$11="Oui")*SUMIFS(Donnees!$B$2:$B$2107,Donnees!$A$2:$A$2107,">="&MAX($AA26,$C$5),Donnees!$A$2:$A$2107,"<="&MIN(EOMONTH($AA26,0),$C$6))+($D$12="Oui")*SUMIFS(Donnees!$C$2:$C$2107,Donnees!$A$2:$A$2107,">="&MAX($AA26,$C$5),Donnees!$A$2:$A$2107,"<="&MIN(EOMONTH($AA26,0),$C$6))+($D$13="Oui")*SUMIFS(Donnees!$D$2:$D$2107,Donnees!$A$2:$A$2107,">="&MAX($AA26,$C$5),Donnees!$A$2:$A$2107,"<="&MIN(EOMONTH($AA26,0),$C$6))+($D$14="Oui")*SUMIFS(Donnees!$E$2:$E$2107,Donnees!$A$2:$A$2107,">="&MAX($AA26,$C$5),Donnees!$A$2:$A$2107,"<="&MIN(EOMONTH($AA26,0),$C$6))+($D$15="Oui")*SUMIFS(Donnees!$F$2:$F$2107,Donnees!$A$2:$A$2107,">="&MAX($AA26,$C$5),Donnees!$A$2:$A$2107,"<="&MIN(EOMONTH($AA26,0),$C$6))+($D$16="Oui")*SUMIFS(Donnees!$G$2:$G$2107,Donnees!$A$2:$A$2107,">="&MAX($AA26,$C$5),Donnees!$A$2:$A$2107,"<="&MIN(EOMONTH($AA26,0),$C$6))+($D$17="Oui")*SUMIFS(Donnees!$H$2:$H$2107,Donnees!$A$2:$A$2107,">="&MAX($AA26,$C$5),Donnees!$A$2:$A$2107,"<="&MIN(EOMONTH($AA26,0),$C$6))+($D$18="Oui")*SUMIFS(Donnees!$I$2:$I$2107,Donnees!$A$2:$A$2107,">="&MAX($AA26,$C$5),Donnees!$A$2:$A$2107,"<="&MIN(EOMONTH($AA26,0),$C$6)),NA()) -> #N/A
AA27: 42125 | AB27: =IF(AND(EOMONTH($AA27,0)>=$C$5,$AA27<=$C$6),($D$11="Oui")*SUMIFS(Donnees!$B$2:$B$2107,Donnees!$A$2:$A$2107,">="&MAX($AA27,$C$5),Donnees!$A$2:$A$2107,"<="&MIN(EOMONTH($AA27,0),$C$6))+($D$12="Oui")*SUMIFS(Donnees!$C$2:$C$2107,Donnees!$A$2:$A$2107,">="&MAX($AA27,$C$5),Donnees!$A$2:$A$2107,"<="&MIN(EOMONTH($AA27,0),$C$6))+($D$13="Oui")*SUMIFS(Donnees!$D$2:$D$2107,Donnees!$A$2:$A$2107,">="&MAX($AA27,$C$5),Donnees!$A$2:$A$2107,"<="&MIN(EOMONTH($AA27,0),$C$6))+($D$14="Oui")*SUMIFS(Donnees!$E$2:$E$2107,Donnees!$A$2:$A$2107,">="&MAX($AA27,$C$5),Donnees!$A$2:$A$2107,"<="&MIN(EOMONTH($AA27,0),$C$6))+($D$15="Oui")*SUMIFS(Donnees!$F$2:$F$2107,Donnees!$A$2:$A$2107,">="&MAX($AA27,$C$5),Donnees!$A$2:$A$2107,"<="&MIN(EOMONTH($AA27,0),$C$6))+($D$16="Oui")*SUMIFS(Donnees!$G$2:$G$2107,Donnees!$A$2:$A$2107,">="&MAX($AA27,$C$5),Donnees!$A$2:$A$2107,"<="&MIN(EOMONTH($AA27,0),$C$6))+($D$17="Oui")*SUMIFS(Donnees!$H$2:$H$2107,Donnees!$A$2:$A$2107,">="&MAX($AA27,$C$5),Donnees!$A$2:$A$2107,"<="&MIN(EOMONTH($AA27,0),$C$6))+($D$18="Oui")*SUMIFS(Donnees!$I$2:$I$2107,Donnees!$A$2:$A$2107,">="&MAX($AA27,$C$5),Donnees!$A$2:$A$2107,"<="&MIN(EOMONTH($AA27,0),$C$6)),NA()) -> #N/A
AA28: 42156 | AB28: =IF(AND(EOMONTH($AA28,0)>=$C$5,$AA28<=$C$6),($D$11="Oui")*SUMIFS(Donnees!$B$2:$B$2107,Donnees!$A$2:$A$2107,">="&MAX($AA28,$C$5),Donnees!$A$2:$A$2107,"<="&MIN(EOMONTH($AA28,0),$C$6))+($D$12="Oui")*SUMIFS(Donnees!$C$2:$C$2107,Donnees!$A$2:$A$2107,">="&MAX($AA28,$C$5),Donnees!$A$2:$A$2107,"<="&MIN(EOMONTH($AA28,0),$C$6))+($D$13="Oui")*SUMIFS(Donnees!$D$2:$D$2107,Donnees!$A$2:$A$2107,">="&MAX($AA28,$C$5),Donnees!$A$2:$A$2107,"<="&MIN(EOMONTH($AA28,0),$C$6))+($D$14="Oui")*SUMIFS(Donnees!$E$2:$E$2107,Donnees!$A$2:$A$2107,">="&MAX($AA28,$C$5),Donnees!$A$2:$A$2107,"<="&MIN(EOMONTH($AA28,0),$C$6))+($D$15="Oui")*SUMIFS(Donnees!$F$2:$F$2107,Donnees!$A$2:$A$2107,">="&MAX($AA28,$C$5),Donnees!$A$2:$A$2107,"<="&MIN(EOMONTH($AA28,0),$C$6))+($D$16="Oui")*SUMIFS(Donnees!$G$2:$G$2107,Donnees!$A$2:$A$2107,">="&MAX($AA28,$C$5),Donnees!$A$2:$A$2107,"<="&MIN(EOMONTH($AA28,0),$C$6))+($D$17="Oui")*SUMIFS(Donnees!$H$2:$H$2107,Donnees!$A$2:$A$2107,">="&MAX($AA28,$C$5),Donnees!$A$2:$A$2107,"<="&MIN(EOMONTH($AA28,0),$C$6))+($D$18="Oui")*SUMIFS(Donnees!$I$2:$I$2107,Donnees!$A$2:$A$2107,">="&MAX($AA28,$C$5),Donnees!$A$2:$A$2107,"<="&MIN(EOMONTH($AA28,0),$C$6)),NA()) -> #N/A
AA29: 42186 | AB29: =IF(AND(EOMONTH($AA29,0)>=$C$5,$AA29<=$C$6),($D$11="Oui")*SUMIFS(Donnees!$B$2:$B$2107,Donnees!$A$2:$A$2107,">="&MAX($AA29,$C$5),Donnees!$A$2:$A$2107,"<="&MIN(EOMONTH($AA29,0),$C$6))+($D$12="Oui")*SUMIFS(Donnees!$C$2:$C$2107,Donnees!$A$2:$A$2107,">="&MAX($AA29,$C$5),Donnees!$A$2:$A$2107,"<="&MIN(EOMONTH($AA29,0),$C$6))+($D$13="Oui")*SUMIFS(Donnees!$D$2:$D$2107,Donnees!$A$2:$A$2107,">="&MAX($AA29,$C$5),Donnees!$A$2:$A$2107,"<="&MIN(EOMONTH($AA29,0),$C$6))+($D$14="Oui")*SUMIFS(Donnees!$E$2:$E$2107,Donnees!$A$2:$A$2107,">="&MAX($AA29,$C$5),Donnees!$A$2:$A$2107,"<="&MIN(EOMONTH($AA29,0),$C$6))+($D$15="Oui")*SUMIFS(Donnees!$F$2:$F$2107,Donnees!$A$2:$A$2107,">="&MAX($AA29,$C$5),Donnees!$A$2:$A$2107,"<="&MIN(EOMONTH($AA29,0),$C$6))+($D$16="Oui")*SUMIFS(Donnees!$G$2:$G$2107,Donnees!$A$2:$A$2107,">="&MAX($AA29,$C$5),Donnees!$A$2:$A$2107,"<="&MIN(EOMONTH($AA29,0),$C$6))+($D$17="Oui")*SUMIFS(Donnees!$H$2:$H$2107,Donnees!$A$2:$A$2107,">="&MAX($AA29,$C$5),Donnees!$A$2:$A$2107,"<="&MIN(EOMONTH($AA29,0),$C$6))+($D$18="Oui")*SUMIFS(Donnees!$I$2:$I$2107,Donnees!$A$2:$A$2107,">="&MAX($AA29,$C$5),Donnees!$A$2:$A$2107,"<="&MIN(EOMONTH($AA29,0),$C$6)),NA()) -> #N/A
AA30: 42217 | AB30: =IF(AND(EOMONTH($AA30,0)>=$C$5,$AA30<=$C$6),($D$11="Oui")*SUMIFS(Donnees!$B$2:$B$2107,Donnees!$A$2:$A$2107,">="&MAX($AA30,$C$5),Donnees!$A$2:$A$2107,"<="&MIN(EOMONTH($AA30,0),$C$6))+($D$12="Oui")*SUMIFS(Donnees!$C$2:$C$2107,Donnees!$A$2:$A$2107,">="&MAX($AA30,$C$5),Donnees!$A$2:$A$2107,"<="&MIN(EOMONTH($AA30,0),$C$6))+($D$13="Oui")*SUMIFS(Donnees!$D$2:$D$2107,Donnees!$A$2:$A$2107,">="&MAX($AA30,$C$5),Donnees!$A$2:$A$2107,"<="&MIN(EOMONTH($AA30,0),$C$6))+($D$14="Oui")*SUMIFS(Donnees!$E$2:$E$2107,Donnees!$A$2:$A$2107,">="&MAX($AA30,$C$5),Donnees!$A$2:$A$2107,"<="&MIN(EOMONTH($AA30,0),$C$6))+($D$15="Oui")*SUMIFS(Donnees!$F$2:$F$2107,Donnees!$A$2:$A$2107,">="&MAX($AA30,$C$5),Donnees!$A$2:$A$2107,"<="&MIN(EOMONTH($AA30,0),$C$6))+($D$16="Oui")*SUMIFS(Donnees!$G$2:$G$2107,Donnees!$A$2:$A$2107,">="&MAX($AA30,$C$5),Donnees!$A$2:$A$2107,"<="&MIN(EOMONTH($AA30,0),$C$6))+($D$17="Oui")*SUMIFS(Donnees!$H$2:$H$2107,Donnees!$A$2:$A$2107,">="&MAX($AA30,$C$5),Donnees!$A$2:$A$2107,"<="&MIN(EOMONTH($AA30,0),$C$6))+($D$18="Oui")*SUMIFS(Donnees!$I$2:$I$2107,Donnees!$A$2:$A$2107,">="&MAX($AA30,$C$5),Donnees!$A$2:$A$2107,"<="&MIN(EOMONTH($AA30,0),$C$6)),NA()) -> #N/A
AA31: 42248 | AB31: =IF(AND(EOMONTH($AA31,0)>=$C$5,$AA31<=$C$6),($D$11="Oui")*SUMIFS(Donnees!$B$2:$B$2107,Donnees!$A$2:$A$2107,">="&MAX($AA31,$C$5),Donnees!$A$2:$A$2107,"<="&MIN(EOMONTH($AA31,0),$C$6))+($D$12="Oui")*SUMIFS(Donnees!$C$2:$C$2107,Donnees!$A$2:$A$2107,">="&MAX($AA31,$C$5),Donnees!$A$2:$A$2107,"<="&MIN(EOMONTH($AA31,0),$C$6))+($D$13="Oui")*SUMIFS(Donnees!$D$2:$D$2107,Donnees!$A$2:$A$2107,">="&MAX($AA31,$C$5),Donnees!$A$2:$A$2107,"<="&MIN(EOMONTH($AA31,0),$C$6))+($D$14="Oui")*SUMIFS(Donnees!$E$2:$E$2107,Donnees!$A$2:$A$2107,">="&MAX($AA31,$C$5),Donnees!$A$2:$A$2107,"<="&MIN(EOMONTH($AA31,0),$C$6))+($D$15="Oui")*SUMIFS(Donnees!$F$2:$F$2107,Donnees!$A$2:$A$2107,">="&MAX($AA31,$C$5),Donnees!$A$2:$A$2107,"<="&MIN(EOMONTH($AA31,0),$C$6))+($D$16="Oui")*SUMIFS(Donnees!$G$2:$G$2107,Donnees!$A$2:$A$2107,">="&MAX($AA31,$C$5),Donnees!$A$2:$A$2107,"<="&MIN(EOMONTH($AA31,0),$C$6))+($D$17="Oui")*SUMIFS(Donnees!$H$2:$H$2107,Donnees!$A$2:$A$2107,">="&MAX($AA31,$C$5),Donnees!$A$2:$A$2107,"<="&MIN(EOMONTH($AA31,0),$C$6))+($D$18="Oui")*SUMIFS(Donnees!$I$2:$I$2107,Donnees!$A$2:$A$2107,">="&MAX($AA31,$C$5),Donnees!$A$2:$A$2107,"<="&MIN(EOMONTH($AA31,0),$C$6)),NA()) -> #N/A
... AA38: 42461 | AB38: =IF(AND(EOMONTH($AA38,0)>=$C$5,$AA38<=$C$6),($D$11="Oui")*SUMIFS(Donnees!$B$2:$B$2107,Donnees!$A$2:$A$2107,">="&MAX($AA38,$C$5),Donnees!$A$2:$A$2107,"<="&MIN(EOMONTH($AA38,0),$C$6))+($D$12="Oui")*SUMIFS(Donnees!$C$2:$C$2107,Donnees!$A$2:$A$2107,">="&MAX($AA38,$C$5),Donnees!$A$2:$A$2107,"<="&MIN(EOMONTH($AA38,0),$C$6))+($D$13="Oui")*SUMIFS(Donnees!$D$2:$D$2107,Donnees!$A$2:$A$2107,">="&MAX($AA38,$C$5),Donnees!$A$2:$A$2107,"<="&MIN(EOMONTH($AA38,0),$C$6))+($D$14="Oui")*SUMIFS(Donnees!$E$2:$E$2107,Donnees!$A$2:$A$2107,">="&MAX($AA38,$C$5),Donnees!$A$2:$A$2107,"<="&MIN(EOMONTH($AA38,0),$C$6))+($D$15="Oui")*SUMIFS(Donnees!$F$2:$F$2107,Donnees!$A$2:$A$2107,">="&MAX($AA38,$C$5),Donnees!$A$2:$A$2107,"<="&MIN(EOMONTH($AA38,0),$C$6))+($D$16="Oui")*SUMIFS(Donnees!$G$2:$G$2107,Donnees!$A$2:$A$2107,">="&MAX($AA38,$C$5),Donnees!$A$2:$A$2107,"<="&MIN(EOMONTH($AA38,0),$C$6))+($D$17="Oui")*SUMIFS(Donnees!$H$2:$H$2107,Donnees!$A$2:$A$2107,">="&MAX($AA38,$C$5),Donnees!$A$2:$A$2107,"<="&MIN(EOMONTH($AA38,0),$C$6))+($D$18="Oui")*SUMIFS(Donnees!$I$2:$I$2107,Donnees!$A$2:$A$2107,">="&MAX($AA38,$C$5),Donnees!$A$2:$A$2107,"<="&MIN(EOMONTH($AA38,0),$C$6)),NA()) -> #N/A
B39: Détail jour par jour sur la période (tous les groupes) | AA39: 42491 | AB39: =IF(AND(EOMONTH($AA39,0)>=$C$5,$AA39<=$C$6),($D$11="Oui")*SUMIFS(Donnees!$B$2:$B$2107,Donnees!$A$2:$A$2107,">="&MAX($AA39,$C$5),Donnees!$A$2:$A$2107,"<="&MIN(EOMONTH($AA39,0),$C$6))+($D$12="Oui")*SUMIFS(Donnees!$C$2:$C$2107,Donnees!$A$2:$A$2107,">="&MAX($AA39,$C$5),Donnees!$A$2:$A$2107,"<="&MIN(EOMONTH($AA39,0),$C$6))+($D$13="Oui")*SUMIFS(Donnees!$D$2:$D$2107,Donnees!$A$2:$A$2107,">="&MAX($AA39,$C$5),Donnees!$A$2:$A$2107,"<="&MIN(EOMONTH($AA39,0),$C$6))+($D$14="Oui")*SUMIFS(Donnees!$E$2:$E$2107,Donnees!$A$2:$A$2107,">="&MAX($AA39,$C$5),Donnees!$A$2:$A$2107,"<="&MIN(EOMONTH($AA39,0),$C$6))+($D$15="Oui")*SUMIFS(Donnees!$F$2:$F$2107,Donnees!$A$2:$A$2107,">="&MAX($AA39,$C$5),Donnees!$A$2:$A$2107,"<="&MIN(EOMONTH($AA39,0),$C$6))+($D$16="Oui")*SUMIFS(Donnees!$G$2:$G$2107,Donnees!$A$2:$A$2107,">="&MAX($AA39,$C$5),Donnees!$A$2:$A$2107,"<="&MIN(EOMONTH($AA39,0),$C$6))+($D$17="Oui")*SUMIFS(Donnees!$H$2:$H$2107,Donnees!$A$2:$A$2107,">="&MAX($AA39,$C$5),Donnees!$A$2:$A$2107,"<="&MIN(EOMONTH($AA39,0),$C$6))+($D$18="Oui")*SUMIFS(Donnees!$I$2:$I$2107,Donnees!$A$2:$A$2107,">="&MAX($AA39,$C$5),Donnees!$A$2:$A$2107,"<="&MIN(EOMONTH($AA39,0),$C$6)),NA()) -> #N/A
B40: Date | C40: M01AB | D40: M01AE | E40: N02BA | F40: N02BE | G40: N05B | H40: N05C | I40: R03 | J40: R06 | AA40: 42522 | AB40: =IF(AND(EOMONTH($AA40,0)>=$C$5,$AA40<=$C$6),($D$11="Oui")*SUMIFS(Donnees!$B$2:$B$2107,Donnees!$A$2:$A$2107,">="&MAX($AA40,$C$5),Donnees!$A$2:$A$2107,"<="&MIN(EOMONTH($AA40,0),$C$6))+($D$12="Oui")*SUMIFS(Donnees!$C$2:$C$2107,Donnees!$A$2:$A$2107,">="&MAX($AA40,$C$5),Donnees!$A$2:$A$2107,"<="&MIN(EOMONTH($AA40,0),$C$6))+($D$13="Oui")*SUMIFS(Donnees!$D$2:$D$2107,Donnees!$A$2:$A$2107,">="&MAX($AA40,$C$5),Donnees!$A$2:$A$2107,"<="&MIN(EOMONTH($AA40,0),$C$6))+($D$14="Oui")*SUMIFS(Donnees!$E$2:$E$2107,Donnees!$A$2:$A$2107,">="&MAX($AA40,$C$5),Donnees!$A$2:$A$2107,"<="&MIN(EOMONTH($AA40,0),$C$6))+($D$15="Oui")*SUMIFS(Donnees!$F$2:$F$2107,Donnees!$A$2:$A$2107,">="&MAX($AA40,$C$5),Donnees!$A$2:$A$2107,"<="&MIN(EOMONTH($AA40,0),$C$6))+($D$16="Oui")*SUMIFS(Donnees!$G$2:$G$2107,Donnees!$A$2:$A$2107,">="&MAX($AA40,$C$5),Donnees!$A$2:$A$2107,"<="&MIN(EOMONTH($AA40,0),$C$6))+($D$17="Oui")*SUMIFS(Donnees!$H$2:$H$2107,Donnees!$A$2:$A$2107,">="&MAX($AA40,$C$5),Donnees!$A$2:$A$2107,"<="&MIN(EOMONTH($AA40,0),$C$6))+($D$18="Oui")*SUMIFS(Donnees!$I$2:$I$2107,Donnees!$A$2:$A$2107,">="&MAX($AA40,$C$5),Donnees!$A$2:$A$2107,"<="&MIN(EOMONTH($AA40,0),$C$6)),NA()) -> #N/A
B41: {=_xlfn._xlws.FILTER(Donnees!$A$2:$I$2107,(Donnees!$A$2:$A$2107>=$C$5)*(Donnees!$A$2:$A$2107<=$C$6),"Aucune donnée")} -> 43709 | C41: 2 | D41: 4.36 | E41: 5 | F41: 17 | G41: 8.2 | H41: 1 | I41: 5 | J41: 4 | AA41: 42552 | AB41: =IF(AND(EOMONTH($AA41,0)>=$C$5,$AA41<=$C$6),($D$11="Oui")*SUMIFS(Donnees!$B$2:$B$2107,Donnees!$A$2:$A$2107,">="&MAX($AA41,$C$5),Donnees!$A$2:$A$2107,"<="&MIN(EOMONTH($AA41,0),$C$6))+($D$12="Oui")*SUMIFS(Donnees!$C$2:$C$2107,Donnees!$A$2:$A$2107,">="&MAX($AA41,$C$5),Donnees!$A$2:$A$2107,"<="&MIN(EOMONTH($AA41,0),$C$6))+($D$13="Oui")*SUMIFS(Donnees!$D$2:$D$2107,Donnees!$A$2:$A$2107,">="&MAX($AA41,$C$5),Donnees!$A$2:$A$2107,"<="&MIN(EOMONTH($AA41,0),$C$6))+($D$14="Oui")*SUMIFS(Donnees!$E$2:$E$2107,Donnees!$A$2:$A$2107,">="&MAX($AA41,$C$5),Donnees!$A$2:$A$2107,"<="&MIN(EOMONTH($AA41,0),$C$6))+($D$15="Oui")*SUMIFS(Donnees!$F$2:$F$2107,Donnees!$A$2:$A$2107,">="&MAX($AA41,$C$5),Donnees!$A$2:$A$2107,"<="&MIN(EOMONTH($AA41,0),$C$6))+($D$16="Oui")*SUMIFS(Donnees!$G$2:$G$2107,Donnees!$A$2:$A$2107,">="&MAX($AA41,$C$5),Donnees!$A$2:$A$2107,"<="&MIN(EOMONTH($AA41,0),$C$6))+($D$17="Oui")*SUMIFS(Donnees!$H$2:$H$2107,Donnees!$A$2:$A$2107,">="&MAX($AA41,$C$5),Donnees!$A$2:$A$2107,"<="&MIN(EOMONTH($AA41,0),$C$6))+($D$18="Oui")*SUMIFS(Donnees!$I$2:$I$2107,Donnees!$A$2:$A$2107,">="&MAX($AA41,$C$5),Donnees!$A$2:$A$2107,"<="&MIN(EOMONTH($AA41,0),$C$6)),NA()) -> #N/A
B42: 43710 | C42: 5.33 | D42: 2.087 | E42: 2.5 | F42: 18 | G42: 7 | H42: 0 | I42: 1 | J42: 9 | AA42: 42583 | AB42: =IF(AND(EOMONTH($AA42,0)>=$C$5,$AA42<=$C$6),($D$11="Oui")*SUMIFS(Donnees!$B$2:$B$2107,Donnees!$A$2:$A$2107,">="&MAX($AA42,$C$5),Donnees!$A$2:$A$2107,"<="&MIN(EOMONTH($AA42,0),$C$6))+($D$12="Oui")*SUMIFS(Donnees!$C$2:$C$2107,Donnees!$A$2:$A$2107,">="&MAX($AA42,$C$5),Donnees!$A$2:$A$2107,"<="&MIN(EOMONTH($AA42,0),$C$6))+($D$13="Oui")*SUMIFS(Donnees!$D$2:$D$2107,Donnees!$A$2:$A$2107,">="&MAX($AA42,$C$5),Donnees!$A$2:$A$2107,"<="&MIN(EOMONTH($AA42,0),$C$6))+($D$14="Oui")*SUMIFS(Donnees!$E$2:$E$2107,Donnees!$A$2:$A$2107,">="&MAX($AA42,$C$5),Donnees!$A$2:$A$2107,"<="&MIN(EOMONTH($AA42,0),$C$6))+($D$15="Oui")*SUMIFS(Donnees!$F$2:$F$2107,Donnees!$A$2:$A$2107,">="&MAX($AA42,$C$5),Donnees!$A$2:$A$2107,"<="&MIN(EOMONTH($AA42,0),$C$6))+($D$16="Oui")*SUMIFS(Donnees!$G$2:$G$2107,Donnees!$A$2:$A$2107,">="&MAX($AA42,$C$5),Donnees!$A$2:$A$2107,"<="&MIN(EOMONTH($AA42,0),$C$6))+($D$17="Oui")*SUMIFS(Donnees!$H$2:$H$2107,Donnees!$A$2:$A$2107,">="&MAX($AA42,$C$5),Donnees!$A$2:$A$2107,"<="&MIN(EOMONTH($AA42,0),$C$6))+($D$18="Oui")*SUMIFS(Donnees!$I$2:$I$2107,Donnees!$A$2:$A$2107,">="&MAX($AA42,$C$5),Donnees!$A$2:$A$2107,"<="&MIN(EOMONTH($AA42,0),$C$6)),NA()) -> #N/A
B43: 43711 | C43: 9.36 | D43: 2.35 | E43: 3.1 | F43: 12.125 | G43: 8 | H43: 3 | I43: 1 | J43: 2 | AA43: 42614 | AB43: =IF(AND(EOMONTH($AA43,0)>=$C$5,$AA43<=$C$6),($D$11="Oui")*SUMIFS(Donnees!$B$2:$B$2107,Donnees!$A$2:$A$2107,">="&MAX($AA43,$C$5),Donnees!$A$2:$A$2107,"<="&MIN(EOMONTH($AA43,0),$C$6))+($D$12="Oui")*SUMIFS(Donnees!$C$2:$C$2107,Donnees!$A$2:$A$2107,">="&MAX($AA43,$C$5),Donnees!$A$2:$A$2107,"<="&MIN(EOMONTH($AA43,0),$C$6))+($D$13="Oui")*SUMIFS(Donnees!$D$2:$D$2107,Donnees!$A$2:$A$2107,">="&MAX($AA43,$C$5),Donnees!$A$2:$A$2107,"<="&MIN(EOMONTH($AA43,0),$C$6))+($D$14="Oui")*SUMIFS(Donnees!$E$2:$E$2107,Donnees!$A$2:$A$2107,">="&MAX($AA43,$C$5),Donnees!$A$2:$A$2107,"<="&MIN(EOMONTH($AA43,0),$C$6))+($D$15="Oui")*SUMIFS(Donnees!$F$2:$F$2107,Donnees!$A$2:$A$2107,">="&MAX($AA43,$C$5),Donnees!$A$2:$A$2107,"<="&MIN(EOMONTH($AA43,0),$C$6))+($D$16="Oui")*SUMIFS(Donnees!$G$2:$G$2107,Donnees!$A$2:$A$2107,">="&MAX($AA43,$C$5),Donnees!$A$2:$A$2107,"<="&MIN(EOMONTH($AA43,0),$C$6))+($D$17="Oui")*SUMIFS(Donnees!$H$2:$H$2107,Donnees!$A$2:$A$2107,">="&MAX($AA43,$C$5),Donnees!$A$2:$A$2107,"<="&MIN(EOMONTH($AA43,0),$C$6))+($D$18="Oui")*SUMIFS(Donnees!$I$2:$I$2107,Donnees!$A$2:$A$2107,">="&MAX($AA43,$C$5),Donnees!$A$2:$A$2107,"<="&MIN(EOMONTH($AA43,0),$C$6)),NA()) -> #N/A
B44: 43712 | C44: 2 | D44: 0.373 | E44: 2.15 | F44: 29.23 | G44: 7 | H44: 0 | I44: 3 | J44: 3 | AA44: 42644 | AB44: =IF(AND(EOMONTH($AA44,0)>=$C$5,$AA44<=$C$6),($D$11="Oui")*SUMIFS(Donnees!$B$2:$B$2107,Donnees!$A$2:$A$2107,">="&MAX($AA44,$C$5),Donnees!$A$2:$A$2107,"<="&MIN(EOMONTH($AA44,0),$C$6))+($D$12="Oui")*SUMIFS(Donnees!$C$2:$C$2107,Donnees!$A$2:$A$2107,">="&MAX($AA44,$C$5),Donnees!$A$2:$A$2107,"<="&MIN(EOMONTH($AA44,0),$C$6))+($D$13="Oui")*SUMIFS(Donnees!$D$2:$D$2107,Donnees!$A$2:$A$2107,">="&MAX($AA44,$C$5),Donnees!$A$2:$A$2107,"<="&MIN(EOMONTH($AA44,0),$C$6))+($D$14="Oui")*SUMIFS(Donnees!$E$2:$E$2107,Donnees!$A$2:$A$2107,">="&MAX($AA44,$C$5),Donnees!$A$2:$A$2107,"<="&MIN(EOMONTH($AA44,0),$C$6))+($D$15="Oui")*SUMIFS(Donnees!$F$2:$F$2107,Donnees!$A$2:$A$2107,">="&MAX($AA44,$C$5),Donnees!$A$2:$A$2107,"<="&MIN(EOMONTH($AA44,0),$C$6))+($D$16="Oui")*SUMIFS(Donnees!$G$2:$G$2107,Donnees!$A$2:$A$2107,">="&MAX($AA44,$C$5),Donnees!$A$2:$A$2107,"<="&MIN(EOMONTH($AA44,0),$C$6))+($D$17="Oui")*SUMIFS(Donnees!$H$2:$H$2107,Donnees!$A$2:$A$2107,">="&MAX($AA44,$C$5),Donnees!$A$2:$A$2107,"<="&MIN(EOMONTH($AA44,0),$C$6))+($D$18="Oui")*SUMIFS(Donnees!$I$2:$I$2107,Donnees!$A$2:$A$2107,">="&MAX($AA44,$C$5),Donnees!$A$2:$A$2107,"<="&MIN(EOMONTH($AA44,0),$C$6)),NA()) -> #N/A
B45: 43713 | C45: 7 | D45: 9.53 | E45: 2 | F45: 14 | G45: 1 | H45: 0 | I45: 1 | J45: 8 | AA45: 42675 | AB45: =IF(AND(EOMONTH($AA45,0)>=$C$5,$AA45<=$C$6),($D$11="Oui")*SUMIFS(Donnees!$B$2:$B$2107,Donnees!$A$2:$A$2107,">="&MAX($AA45,$C$5),Donnees!$A$2:$A$2107,"<="&MIN(EOMONTH($AA45,0),$C$6))+($D$12="Oui")*SUMIFS(Donnees!$C$2:$C$2107,Donnees!$A$2:$A$2107,">="&MAX($AA45,$C$5),Donnees!$A$2:$A$2107,"<="&MIN(EOMONTH($AA45,0),$C$6))+($D$13="Oui")*SUMIFS(Donnees!$D$2:$D$2107,Donnees!$A$2:$A$2107,">="&MAX($AA45,$C$5),Donnees!$A$2:$A$2107,"<="&MIN(EOMONTH($AA45,0),$C$6))+($D$14="Oui")*SUMIFS(Donnees!$E$2:$E$2107,Donnees!$A$2:$A$2107,">="&MAX($AA45,$C$5),Donnees!$A$2:$A$2107,"<="&MIN(EOMONTH($AA45,0),$C$6))+($D$15="Oui")*SUMIFS(Donnees!$F$2:$F$2107,Donnees!$A$2:$A$2107,">="&MAX($AA45,$C$5),Donnees!$A$2:$A$2107,"<="&MIN(EOMONTH($AA45,0),$C$6))+($D$16="Oui")*SUMIFS(Donnees!$G$2:$G$2107,Donnees!$A$2:$A$2107,">="&MAX($AA45,$C$5),Donnees!$A$2:$A$2107,"<="&MIN(EOMONTH($AA45,0),$C$6))+($D$17="Oui")*SUMIFS(Donnees!$H$2:$H$2107,Donnees!$A$2:$A$2107,">="&MAX($AA45,$C$5),Donnees!$A$2:$A$2107,"<="&MIN(EOMONTH($AA45,0),$C$6))+($D$18="Oui")*SUMIFS(Donnees!$I$2:$I$2107,Donnees!$A$2:$A$2107,">="&MAX($AA45,$C$5),Donnees!$A$2:$A$2107,"<="&MIN(EOMONTH($AA45,0),$C$6)),NA()) -> #N/A
B46: 43714 | C46: 1.68 | D46: 2.67 | E46: 1 | F46: 28.4 | G46: 7 | H46: 0 | I46: 0 | J46: 1.5 | AA46: 42705 | AB46: =IF(AND(EOMONTH($AA46,0)>=$C$5,$AA46<=$C$6),($D$11="Oui")*SUMIFS(Donnees!$B$2:$B$2107,Donnees!$A$2:$A$2107,">="&MAX($AA46,$C$5),Donnees!$A$2:$A$2107,"<="&MIN(EOMONTH($AA46,0),$C$6))+($D$12="Oui")*SUMIFS(Donnees!$C$2:$C$2107,Donnees!$A$2:$A$2107,">="&MAX($AA46,$C$5),Donnees!$A$2:$A$2107,"<="&MIN(EOMONTH($AA46,0),$C$6))+($D$13="Oui")*SUMIFS(Donnees!$D$2:$D$2107,Donnees!$A$2:$A$2107,">="&MAX($AA46,$C$5),Donnees!$A$2:$A$2107,"<="&MIN(EOMONTH($AA46,0),$C$6))+($D$14="Oui")*SUMIFS(Donnees!$E$2:$E$2107,Donnees!$A$2:$A$2107,">="&MAX($AA46,$C$5),Donnees!$A$2:$A$2107,"<="&MIN(EOMONTH($AA46,0),$C$6))+($D$15="Oui")*SUMIFS(Donnees!$F$2:$F$2107,Donnees!$A$2:$A$2107,">="&MAX($AA46,$C$5),Donnees!$A$2:$A$2107,"<="&MIN(EOMONTH($AA46,0),$C$6))+($D$16="Oui")*SUMIFS(Donnees!$G$2:$G$2107,Donnees!$A$2:$A$2107,">="&MAX($AA46,$C$5),Donnees!$A$2:$A$2107,"<="&MIN(EOMONTH($AA46,0),$C$6))+($D$17="Oui")*SUMIFS(Donnees!$H$2:$H$2107,Donnees!$A$2:$A$2107,">="&MAX($AA46,$C$5),Donnees!$A$2:$A$2107,"<="&MIN(EOMONTH($AA46,0),$C$6))+($D$18="Oui")*SUMIFS(Donnees!$I$2:$I$2107,Donnees!$A$2:$A$2107,">="&MAX($AA46,$C$5),Donnees!$A$2:$A$2107,"<="&MIN(EOMONTH($AA46,0),$C$6)),NA()) -> #N/A
B47: 43715 | C47: 8.33 | D47: 3.67 | E47: 2 | F47: 27 | G47: 14 | H47: 3 | I47: 6 | J47: 2 | AA47: 42736 | AB47: =IF(AND(EOMONTH($AA47,0)>=$C$5,$AA47<=$C$6),($D$11="Oui")*SUMIFS(Donnees!$B$2:$B$2107,Donnees!$A$2:$A$2107,">="&MAX($AA47,$C$5),Donnees!$A$2:$A$2107,"<="&MIN(EOMONTH($AA47,0),$C$6))+($D$12="Oui")*SUMIFS(Donnees!$C$2:$C$2107,Donnees!$A$2:$A$2107,">="&MAX($AA47,$C$5),Donnees!$A$2:$A$2107,"<="&MIN(EOMONTH($AA47,0),$C$6))+($D$13="Oui")*SUMIFS(Donnees!$D$2:$D$2107,Donnees!$A$2:$A$2107,">="&MAX($AA47,$C$5),Donnees!$A$2:$A$2107,"<="&MIN(EOMONTH($AA47,0),$C$6))+($D$14="Oui")*SUMIFS(Donnees!$E$2:$E$2107,Donnees!$A$2:$A$2107,">="&MAX($AA47,$C$5),Donnees!$A$2:$A$2107,"<="&MIN(EOMONTH($AA47,0),$C$6))+($D$15="Oui")*SUMIFS(Donnees!$F$2:$F$2107,Donnees!$A$2:$A$2107,">="&MAX($AA47,$C$5),Donnees!$A$2:$A$2107,"<="&MIN(EOMONTH($AA47,0),$C$6))+($D$16="Oui")*SUMIFS(Donnees!$G$2:$G$2107,Donnees!$A$2:$A$2107,">="&MAX($AA47,$C$5),Donnees!$A$2:$A$2107,"<="&MIN(EOMONTH($AA47,0),$C$6))+($D$17="Oui")*SUMIFS(Donnees!$H$2:$H$2107,Donnees!$A$2:$A$2107,">="&MAX($AA47,$C$5),Donnees!$A$2:$A$2107,"<="&MIN(EOMONTH($AA47,0),$C$6))+($D$18="Oui")*SUMIFS(Donnees!$I$2:$I$2107,Donnees!$A$2:$A$2107,">="&MAX($AA47,$C$5),Donnees!$A$2:$A$2107,"<="&MIN(EOMONTH($AA47,0),$C$6)),NA()) -> #N/A
B48: 43716 | C48: 7.01 | D48: 6.087 | E48: 3 | F48: 26 | G48: 7 | H48: 0 | I48: 3 | J48: 3 | AA48: 42767 | AB48: =IF(AND(EOMONTH($AA48,0)>=$C$5,$AA48<=$C$6),($D$11="Oui")*SUMIFS(Donnees!$B$2:$B$2107,Donnees!$A$2:$A$2107,">="&MAX($AA48,$C$5),Donnees!$A$2:$A$2107,"<="&MIN(EOMONTH($AA48,0),$C$6))+($D$12="Oui")*SUMIFS(Donnees!$C$2:$C$2107,Donnees!$A$2:$A$2107,">="&MAX($AA48,$C$5),Donnees!$A$2:$A$2107,"<="&MIN(EOMONTH($AA48,0),$C$6))+($D$13="Oui")*SUMIFS(Donnees!$D$2:$D$2107,Donnees!$A$2:$A$2107,">="&MAX($AA48,$C$5),Donnees!$A$2:$A$2107,"<="&MIN(EOMONTH($AA48,0),$C$6))+($D$14="Oui")*SUMIFS(Donnees!$E$2:$E$2107,Donnees!$A$2:$A$2107,">="&MAX($AA48,$C$5),Donnees!$A$2:$A$2107,"<="&MIN(EOMONTH($AA48,0),$C$6))+($D$15="Oui")*SUMIFS(Donnees!$F$2:$F$2107,Donnees!$A$2:$A$2107,">="&MAX($AA48,$C$5),Donnees!$A$2:$A$2107,"<="&MIN(EOMONTH($AA48,0),$C$6))+($D$16="Oui")*SUMIFS(Donnees!$G$2:$G$2107,Donnees!$A$2:$A$2107,">="&MAX($AA48,$C$5),Donnees!$A$2:$A$2107,"<="&MIN(EOMONTH($AA48,0),$C$6))+($D$17="Oui")*SUMIFS(Donnees!$H$2:$H$2107,Donnees!$A$2:$A$2107,">="&MAX($AA48,$C$5),Donnees!$A$2:$A$2107,"<="&MIN(EOMONTH($AA48,0),$C$6))+($D$18="Oui")*SUMIFS(Donnees!$I$2:$I$2107,Donnees!$A$2:$A$2107,">="&MAX($AA48,$C$5),Donnees!$A$2:$A$2107,"<="&MIN(EOMONTH($AA48,0),$C$6)),NA()) -> #N/A
B49: 43717 | C49: 1.18 | D49: 2.124 | E49: 3 | F49: 26 | G49: 4 | H49: 3 | I49: 5 | J49: 2 | AA49: 42795 | AB49: =IF(AND(EOMONTH($AA49,0)>=$C$5,$AA49<=$C$6),($D$11="Oui")*SUMIFS(Donnees!$B$2:$B$2107,Donnees!$A$2:$A$2107,">="&MAX($AA49,$C$5),Donnees!$A$2:$A$2107,"<="&MIN(EOMONTH($AA49,0),$C$6))+($D$12="Oui")*SUMIFS(Donnees!$C$2:$C$2107,Donnees!$A$2:$A$2107,">="&MAX($AA49,$C$5),Donnees!$A$2:$A$2107,"<="&MIN(EOMONTH($AA49,0),$C$6))+($D$13="Oui")*SUMIFS(Donnees!$D$2:$D$2107,Donnees!$A$2:$A$2107,">="&MAX($AA49,$C$5),Donnees!$A$2:$A$2107,"<="&MIN(EOMONTH($AA49,0),$C$6))+($D$14="Oui")*SUMIFS(Donnees!$E$2:$E$2107,Donnees!$A$2:$A$2107,">="&MAX($AA49,$C$5),Donnees!$A$2:$A$2107,"<="&MIN(EOMONTH($AA49,0),$C$6))+($D$15="Oui")*SUMIFS(Donnees!$F$2:$F$2107,Donnees!$A$2:$A$2107,">="&MAX($AA49,$C$5),Donnees!$A$2:$A$2107,"<="&MIN(EOMONTH($AA49,0),$C$6))+($D$16="Oui")*SUMIFS(Donnees!$G$2:$G$2107,Donnees!$A$2:$A$2107,">="&MAX($AA49,$C$5),Donnees!$A$2:$A$2107,"<="&MIN(EOMONTH($AA49,0),$C$6))+($D$17="Oui")*SUMIFS(Donnees!$H$2:$H$2107,Donnees!$A$2:$A$2107,">="&MAX($AA49,$C$5),Donnees!$A$2:$A$2107,"<="&MIN(EOMONTH($AA49,0),$C$6))+($D$18="Oui")*SUMIFS(Donnees!$I$2:$I$2107,Donnees!$A$2:$A$2107,">="&MAX($AA49,$C$5),Donnees!$A$2:$A$2107,"<="&MIN(EOMONTH($AA49,0),$C$6)),NA()) -> #N/A
B50: 43718 | C50: 8.66 | D50: 6.68 | E50: 4.2 | F50: 22 | G50: 17 | H50: 0 | I50: 1 | J50: 1 | AA50: 42826 | AB50: =IF(AND(EOMONTH($AA50,0)>=$C$5,$AA50<=$C$6),($D$11="Oui")*SUMIFS(Donnees!$B$2:$B$2107,Donnees!$A$2:$A$2107,">="&MAX($AA50,$C$5),Donnees!$A$2:$A$2107,"<="&MIN(EOMONTH($AA50,0),$C$6))+($D$12="Oui")*SUMIFS(Donnees!$C$2:$C$2107,Donnees!$A$2:$A$2107,">="&MAX($AA50,$C$5),Donnees!$A$2:$A$2107,"<="&MIN(EOMONTH($AA50,0),$C$6))+($D$13="Oui")*SUMIFS(Donnees!$D$2:$D$2107,Donnees!$A$2:$A$2107,">="&MAX($AA50,$C$5),Donnees!$A$2:$A$2107,"<="&MIN(EOMONTH($AA50,0),$C$6))+($D$14="Oui")*SUMIFS(Donnees!$E$2:$E$2107,Donnees!$A$2:$A$2107,">="&MAX($AA50,$C$5),Donnees!$A$2:$A$2107,"<="&MIN(EOMONTH($AA50,0),$C$6))+($D$15="Oui")*SUMIFS(Donnees!$F$2:$F$2107,Donnees!$A$2:$A$2107,">="&MAX($AA50,$C$5),Donnees!$A$2:$A$2107,"<="&MIN(EOMONTH($AA50,0),$C$6))+($D$16="Oui")*SUMIFS(Donnees!$G$2:$G$2107,Donnees!$A$2:$A$2107,">="&MAX($AA50,$C$5),Donnees!$A$2:$A$2107,"<="&MIN(EOMONTH($AA50,0),$C$6))+($D$17="Oui")*SUMIFS(Donnees!$H$2:$H$2107,Donnees!$A$2:$A$2107,">="&MAX($AA50,$C$5),Donnees!$A$2:$A$2107,"<="&MIN(EOMONTH($AA50,0),$C$6))+($D$18="Oui")*SUMIFS(Donnees!$I$2:$I$2107,Donnees!$A$2:$A$2107,">="&MAX($AA50,$C$5),Donnees!$A$2:$A$2107,"<="&MIN(EOMONTH($AA50,0),$C$6)),NA()) -> #N/A
...

Sheet Stats
B2: Statistiques descriptives (mois complets uniquement)
B4: Groupe ATC | C4: Libellé | D4: Total | E4: Part du volume | F4: Moyenne par jour | G4: Médiane par jour | H4: Écart-type | I4: Coef. de variation | J4: Jours sans vente | K4: Évolution annuelle moyenne | L4: Mois de pic | M4: Indice du pic | N4: Mois creux | O4: Jour le plus fort
B5: M01AB | C5: Anti-inflammatoires (type diclofénac) | D5: 10679.625 | E5: 0.083026536 | F5: 5.0903837 | G5: 4.99 | H5: 2.71279 | I5: 0.53292447 | J5: 14 | K5: 0.056114242 | L5: Août | M5: 107 | N5: Juin | O5: Samedi
B6: M01AE | C6: Anti-inflammatoires (type ibuprofène) | D6: 8293.549 | E6: 0.064476482 | F6: 3.9530739 | G6: 3.675 | H6: 2.1190956 | I6: 0.53606274 | J6: 10 | K6: 0.025176825 | L6: Janv. | M6: 118 | N6: Juin | O6: Dimanche
B7: N02BA | C7: Antalgiques salicylés (type aspirine) | D7: 8169.0097 | E7: 0.063508276 | F7: 3.8937129 | G7: 3.5 | H7: 2.3428604 | I7: 0.60170343 | J7: 54 | K7: -0.085300816 | L7: Févr. | M7: 121 | N7: Sept. | O7: Mardi
B8: N02BE | C8: Antalgiques (type paracétamol) | D8: 63856.431 | E8: 0.49643862 | F8: 30.436812 | G8: 27 | H8: 15.838967 | I8: 0.52038851 | J8: 0 | K8: 0.053854108 | L8: Janv. | M8: 143 | N8: Juil. | O8: Dimanche
B9: N05B | C9: Anxiolytiques | D9: 18527.008 | E9: 0.1440344 | F9: 8.8307952 | G9: 8 | H9: 5.5320401 | I9: 0.62644869 | J9: 18 | K9: -0.067219566 | L9: Janv. | M9: 116 | N9: Mai | O9: Mercredi
B10: N05C | C10: Hypnotiques et sédatifs | D10: 1242 | E10: 0.0096556722 | F10: 0.59199237 | G10: 0 | H10: 1.0959555 | I10: 1.8513001 | J10: 1432 | K10: -0.030687979 | L10: Janv. | M10: 127 | N10: Avr. | O10: Vendredi
B11: R03 | C11: Asthme et BPCO | D11: 11708.083 | E11: 0.091022073 | F11: 5.5805926 | G11: 4 | H11: 6.4921552 | I11: 1.1633451 | J11: 471 | K11: 0.211559 | L11: Déc. | M11: 148 | N11: Juil. | O11: Lundi
B12: R06 | C12: Antihistaminiques | D12: 6153.35 | E12: 0.047837947 | F12: 2.93296 | G12: 2 | H12: 2.4203131 | I12: 0.82521177 | J12: 241 | K12: 0.10450179 | L12: Mai | M12: 176 | N12: Déc. | O12: Samedi
B14: Indice par mois (100 = mois moyen du groupe)
B15: Groupe | C15: Janv. | D15: Févr. | E15: Mars | F15: Avr. | G15: Mai | H15: Juin | I15: Juil. | J15: Août | K15: Sept. | L15: Oct. | M15: Nov. | N15: Déc.
B16: Anti-inflammatoires (type diclofénac) (M01AB) | C16: 104 | D16: 97 | E16: 97 | F16: 103 | G16: 96 | H16: 93 | I16: 102 | J16: 107 | K16: 98 | L16: 97 | M16: 103 | N16: 103
B17: Anti-inflammatoires (type ibuprofène) (M01AE) | C17: 118 | D17: 118 | E17: 98 | F17: 94 | G17: 94 | H17: 90 | I17: 95 | J17: 92 | K17: 100 | L17: 98 | M17: 96 | N17: 106
B18: Antalgiques salicylés (type aspirine) (N02BA) | C18: 115 | D18: 121 | E18: 102 | F18: 97 | G18: 96 | H18: 96 | I18: 89 | J18: 89 | K18: 86 | L18: 104 | M18: 107 | N18: 98
B19: Antalgiques (type paracétamol) (N02BE) | C19: 143 | D19: 118 | E19: 97 | F19: 87 | G19: 75 | H19: 67 | I19: 63 | J19: 67 | K19: 104 | L19: 138 | M19: 106 | N19: 135
B20: Anxiolytiques (N05B) | C20: 116 | D20: 100 | E20: 93 | F20: 91 | G20: 85 | H20: 89 | I20: 94 | J20: 103 | K20: 104 | L20: 106 | M20: 105 | N20: 113
B21: Hypnotiques et sédatifs (N05C) | C21: 127 | D21: 91 | E21: 105 | F21: 81 | G21: 103 | H21: 99 | I21: 81 | J21: 103 | K21: 88 | L21: 85 | M21: 114 | N21: 123
B22: Asthme et BPCO (R03) | C22: 126 | D22: 120 | E22: 111 | F22: 103 | G22: 89 | H22: 77 | I22: 52 | J22: 55 | K22: 78 | L22: 130 | M22: 110 | N22: 148
B23: Antihistaminiques (R06) | C23: 56 | D23: 58 | E23: 111 | F23: 171 | G23: 176 | H23: 154 | I23: 117 | J23: 94 | K23: 89 | L23: 69 | M23: 55 | N23: 51
B25: Indice par jour de semaine (100 = jour moyen du groupe)
B26: Groupe | C26: Lundi | D26: Mardi | E26: Mercredi | F26: Jeudi | G26: Vendredi | H26: Samedi | I26: Dimanche
B27: Anti-inflammatoires (type diclofénac) (M01AB) | C27: 101 | D27: 100 | E27: 93 | F27: 90 | G27: 95 | H27: 114 | I27: 107
B28: Anti-inflammatoires (type ibuprofène) (M01AE) | C28: 96 | D28: 91 | E28: 94 | F28: 93 | G28: 95 | H28: 111 | I28: 119
B29: Antalgiques salicylés (type aspirine) (N02BA) | C29: 101 | D29: 110 | E29: 95 | F29: 96 | G29: 100 | H29: 108 | I29: 90
B30: Antalgiques (type paracétamol) (N02BE) | C30: 98 | D30: 94 | E30: 93 | F30: 94 | G30: 96 | H30: 112 | I30: 114
B31: Anxiolytiques (N05B) | C31: 105 | D31: 108 | E31: 114 | F31: 99 | G31: 112 | H31: 97 | I31: 65
B32: Hypnotiques et sédatifs (N05C) | C32: 104 | D32: 119 | E32: 112 | F32: 90 | G32: 129 | H32: 92 | I32: 53
B33: Asthme et BPCO (R03) | C33: 108 | D33: 97 | E33: 99 | F33: 97 | G33: 104 | H33: 101 | I33: 94
B34: Antihistaminiques (R06) | C34: 99 | D34: 105 | E34: 92 | F34: 90 | G34: 95 | H34: 112 | I34: 106
B36: Indice par heure (100 = heure moyenne du groupe, export horaire)
B37: Groupe | C37: 0h | D37: 1h | E37: 2h | F37: 3h | G37: 4h | H37: 5h | I37: 6h | J37: 7h | K37: 8h | L37: 9h | M37: 10h | N37: 11h | O37: 12h | P37: 13h | Q37: 14h | R37: 15h | S37: 16h | T37: 17h | U37: 18h | V37: 19h | W37: 20h | X37: 21h | Y37: 22h | Z37: 23h
B38: Anti-inflammatoires (type diclofénac) (M01AB) | C38: 0 | D38: 0 | E38: 0 | F38: 0 | G38: 0 | H38: 0 | I38: 0 | J38: 7 | K38: 129 | L38: 170 | M38: 197 | N38: 222 | O38: 211 | P38: 184 | Q38: 194 | R38: 145 | S38: 134 | T38: 140 | U38: 167 | V38: 199 | W38: 181 | X38: 119 | Y38: 1 | Z38: 0
B39: Anti-inflammatoires (type ibuprofène) (M01AE) | C39: 0 | D39: 0 | E39: 0 | F39: 0 | G39: 0 | H39: 0 | I39: 0 | J39: 11 | K39: 97 | L39: 133 | M39: 162 | N39: 195 | O39: 188 | P39: 162 | Q39: 171 | R39: 148 | S39: 154 | T39: 174 | U39: 193 | V39: 236 | W39: 243 | X39: 133 | Y39: 1 | Z39: 0
B40: Antalgiques salicylés (type aspirine) (N02BA) | C40: 0 | D40: 0 | E40: 0 | F40: 0 | G40: 0 | H40: 0 | I40: 0 | J40: 7 | K40: 129 | L40: 210 | M40: 250 | N40: 249 | O40: 214 | P40: 198 | Q40: 154 | R40: 137 | S40: 119 | T40: 135 | U40: 182 | V40: 170 | W40: 161 | X40: 83 | Y40: 1 | Z40: 0
B41: Antalgiques (type paracétamol) (N02BE) | C41: 0 | D41: 0 | E41: 0 | F41: 0 | G41: 0 | H41: 0 | I41: 0 | J41: 13 | K41: 105 | L41: 138 | M41: 159 | N41: 186 | O41: 194 | P41: 165 | Q41: 159 | R41: 161 | S41: 160 | T41: 166 | U41: 198 | V41: 228 | W41: 228 | X41: 138 | Y41: 1 | Z41: 0
B42: Anxiolytiques (N05B) | C42: 0 | D42: 0 | E42: 0 | F42: 0 | G42: 0 | H42: 0 | I42: 0 | J42: 8 | K42: 136 | L42: 188 | M42: 238 | N42: 261 | O42: 245 | P42: 223 | Q42: 174 | R42: 151 | S42: 138 | T42: 131 | U42: 149 | V42: 151 | W42: 132 | X42: 74 | Y42: 1 | Z42: 0
B43: Hypnotiques et sédatifs (N05C) | C43: 0 | D43: 0 | E43: 0 | F43: 0 | G43: 0 | H43: 0 | I43: 0 | J43: 8 | K43: 97 | L43: 126 | M43: 180 | N43: 187 | O43: 230 | P43: 267 | Q43: 184 | R43: 213 | S43: 170 | T43: 153 | U43: 195 | V43: 166 | W43: 168 | X43: 58 | Y43: 0 | Z43: 0
B44: Asthme et BPCO (R03) | C44: 0 | D44: 0 | E44: 0 | F44: 0 | G44: 0 | H44: 0 | I44: 0 | J44: 12 | K44: 138 | L44: 151 | M44: 176 | N44: 169 | O44: 139 | P44: 159 | Q44: 153 | R44: 139 | S44: 122 | T44: 167 | U44: 231 | V44: 254 | W44: 253 | X44: 134 | Y44: 2 | Z44: 0
B45: Antihistaminiques (R06) | C45: 0 | D45: 0 | E45: 0 | F45: 0 | G45: 0 | H45: 0 | I45: 0 | J45: 7 | K45: 109 | L45: 146 | M45: 184 | N45: 190 | O45: 196 | P45: 186 | Q45: 158 | R45: 147 | S45: 126 | T45: 136 | U45: 202 | V45: 227 | W45: 237 | X45: 148 | Y45: 0 | Z45: 0

Sheet Prevision
B2: Tendance, saisonnalité et prévision de octobre 2019
B4: 1. Y a-t-il une tendance, une saisonnalité, ou les deux ?
B5: Tests sur la vente moyenne par jour de chaque mois complet. Une p-value sous 0.05 signale un effet peu compatible avec le hasard.
B6: Libellé | C6: Code | D6: Pente par an (% du niveau moyen) | E6: p-value tendance | F6: p-value saisonnalité | G6: Part de variance expliquée (R²) | H6: Structure détectée
B7: Anti-inflammatoires (type diclofénac) | C7: M01AB | D7: 0.032900268 | E7: 0.002241682 | F7: 0.88041365 | G7: 0.22296515 | H7: Tendance seule
B8: Anti-inflammatoires (type ibuprofène) | C8: M01AE | D8: 0.0068628692 | E8: 0.53543158 | F8: 0.023879635 | G8: 0.30708442 | H8: Saisonnalité seule
B9: Antalgiques salicylés (type aspirine) | C9: N02BA | D9: -0.085416011 | E9: 2.7013948e-12 | F9: 0.0074505347 | G9: 0.68129452 | H9: Tendance + saisonnalité
B10: Antalgiques (type paracétamol) | C10: N02BE | D10: 0.014052542 | E10: 0.35959679 | F10: 1.3131042e-10 | G10: 0.68788976 | H10: Saisonnalité seule
B11: Anxiolytiques | C11: N05B | D11: -0.054246939 | E11: 0.0095548071 | F11: 0.75870243 | G11: 0.20827282 | H11: Tendance seule
B12: Hypnotiques et sédatifs | C12: N05C | D12: 0.010024037 | E12: 0.74342036 | F12: 0.65925705 | G12: 0.13340185 | H12: Ni l'une ni l'autre
